Workbook

Sheet 关卡总览
A2: 翠绿原野 · 第一章关卡参考 | B2: 翠绿原野 · 第一章关卡参考 | C2: 翠绿原野 · 第一章关卡参考 | D2: 翠绿原野 · 第一章关卡参考 | E2: 翠绿原野 · 第一章关卡参考 | F2: 翠绿原野 · 第一章关卡参考 | G2: 翠绿原野 · 第一章关卡参考 | H2: 翠绿原野 · 第一章关卡参考 | I2: 翠绿原野 · 第一章关卡参考 | J2: 翠绿原野 · 第一章关卡参考 | K2: 翠绿原野 · 第一章关卡参考 | L2: 翠绿原野 · 第一章关卡参考 | M2: 翠绿原野 · 第一章关卡参考
A4: CH1-v0.1 / 2026-10-09。黄色可调、白色公式、灰色当前资源。参考脚本不是实测，修改表格不会修改游戏。 | B4: CH1-v0.1 / 2026-10-09。黄色可调、白色公式、灰色当前资源。参考脚本不是实测，修改表格不会修改游戏。 | C4: CH1-v0.1 / 2026-10-09。黄色可调、白色公式、灰色当前资源。参考脚本不是实测，修改表格不会修改游戏。 | D4: CH1-v0.1 / 2026-10-09。黄色可调、白色公式、灰色当前资源。参考脚本不是实测，修改表格不会修改游戏。 | E4: CH1-v0.1 / 2026-10-09。黄色可调、白色公式、灰色当前资源。参考脚本不是实测，修改表格不会修改游戏。 | F4: CH1-v0.1 / 2026-10-09。黄色可调、白色公式、灰色当前资源。参考脚本不是实测，修改表格不会修改游戏。 | G4: CH1-v0.1 / 2026-10-09。黄色可调、白色公式、灰色当前资源。参考脚本不是实测，修改表格不会修改游戏。 | H4: CH1-v0.1 / 2026-10-09。黄色可调、白色公式、灰色当前资源。参考脚本不是实测，修改表格不会修改游戏。 | I4: CH1-v0.1 / 2026-10-09。黄色可调、白色公式、灰色当前资源。参考脚本不是实测，修改表格不会修改游戏。 | J4: CH1-v0.1 / 2026-10-09。黄色可调、白色公式、灰色当前资源。参考脚本不是实测，修改表格不会修改游戏。 | K4: CH1-v0.1 / 2026-10-09。黄色可调、白色公式、灰色当前资源。参考脚本不是实测，修改表格不会修改游戏。 | L4: CH1-v0.1 / 2026-10-09。黄色可调、白色公式、灰色当前资源。参考脚本不是实测，修改表格不会修改游戏。 | M4: CH1-v0.1 / 2026-10-09。黄色可调、白色公式、灰色当前资源。参考脚本不是实测，修改表格不会修改游戏。
A6: 统一采用当前起始牌组；不计地形、天气、站位收益，不依赖药水或新增强力卡。 | B6: 统一采用当前起始牌组；不计地形、天气、站位收益，不依赖药水或新增强力卡。 | C6: 统一采用当前起始牌组；不计地形、天气、站位收益，不依赖药水或新增强力卡。 | D6: 统一采用当前起始牌组；不计地形、天气、站位收益，不依赖药水或新增强力卡。 | E6: 统一采用当前起始牌组；不计地形、天气、站位收益，不依赖药水或新增强力卡。 | F6: 统一采用当前起始牌组；不计地形、天气、站位收益，不依赖药水或新增强力卡。 | G6: 统一采用当前起始牌组；不计地形、天气、站位收益，不依赖药水或新增强力卡。 | H6: 统一采用当前起始牌组；不计地形、天气、站位收益，不依赖药水或新增强力卡。 | I6: 统一采用当前起始牌组；不计地形、天气、站位收益，不依赖药水或新增强力卡。 | J6: 统一采用当前起始牌组；不计地形、天气、站位收益，不依赖药水或新增强力卡。 | K6: 统一采用当前起始牌组；不计地形、天气、站位收益，不依赖药水或新增强力卡。 | L6: 统一采用当前起始牌组；不计地形、天气、站位收益，不依赖药水或新增强力卡。 | M6: 统一采用当前起始牌组；不计地形、天气、站位收益，不依赖药水或新增强力卡。
A8: 编号 | B8: 关卡 | C8: 适用层 | D8: 据点生命 | E8: 首轮能量 | F8: 成长/轮 | G8: 能量上限 | H8: 抽牌/轮 | I8: 参考轮数 | J8: 参考战损 | K8: 脚本状态 | L8: 轮数目标 | M8: 战损目标
A9: A | B9: 原野初遇 | C9: 第2层 | D9: 22 | E9: 3 | F9: 1 | G9: 10 | H9: 5 | I9: =IF(波次与结算!P14>0,"待继续",COUNTIF(波次与结算!P9:P14,">0")+1) -> 5 | J9: =波次与结算!Q14 -> 4 | K9: =IF(波次与结算!P14>0,"未扣完","已扣完") -> 已扣完 | L9: 4–6 | M9: 0–8
A10: B | B10: 边境混编 | C10: 第4层战斗 | D10: 30 | E10: 3 | F10: 1 | G10: 10 | H10: 5 | I10: =IF(波次与结算!P22>0,"待继续",COUNTIF(波次与结算!P16:P22,">0")+1) -> 7 | J10: =波次与结算!Q22 -> 12 | K10: =IF(波次与结算!P22>0,"未扣完","已扣完") -> 已扣完 | L10: 5–7 | M10: 6–14
A11: C | B11: 补给线阻击 | C11: 第5层战斗 | D11: 34 | E11: 3 | F11: 1 | G11: 10 | H11: 5 | I11: =IF(波次与结算!P30>0,"待继续",COUNTIF(波次与结算!P24:P30,">0")+1) -> 7 | J11: =波次与结算!Q30 -> 12 | K11: =IF(波次与结算!P30>0,"未扣完","已扣完") -> 已扣完 | L11: 6–8 | M11: 8–16
A12: D | B12: 原野守军 | C12: 第7层战斗 | D12: 38 | E12: 3 | F12: 1 | G12: 10 | H12: 5 | I12: =IF(波次与结算!P39>0,"待继续",COUNTIF(波次与结算!P32:P39,">0")+1) -> 8 | J12: =波次与结算!Q39 -> 12 | K12: =IF(波次与结算!P39>0,"未扣完","已扣完") -> 已扣完 | L12: 6–8 | M12: 8–18
A13: E | B13: 督军前哨 | C13: 第8层战斗 | D13: 42 | E13: 3 | F13: 1 | G13: 10 | H13: 5 | I13: =IF(波次与结算!P49>0,"待继续",COUNTIF(波次与结算!P41:P49,">0")+1) -> 9 | J13: =波次与结算!Q49 -> 16 | K13: =IF(波次与结算!P49>0,"未扣完","已扣完") -> 已扣完 | L13: 7–9 | M13: 10–22
A14: F | B14: 原野督军 | C14: 第10层Boss | D14: 52 | E14: 3 | F14: 1 | G14: 10 | H14: 5 | I14: =IF(波次与结算!P65>0,"待继续",COUNTIF(波次与结算!P51:P65,">0")+1) -> 10 | J14: =波次与结算!Q65 -> 22 | K14: =IF(波次与结算!P65>0,"未扣完","已扣完") -> 已扣完 | L14: 8–11 | M14: 16–34
A16: 据点生命控制需要赢几轮；敌兵属性与编成控制某一轮是否能赢。两者分开调整。 | B16: 据点生命控制需要赢几轮；敌兵属性与编成控制某一轮是否能赢。两者分开调整。 | C16: 据点生命控制需要赢几轮；敌兵属性与编成控制某一轮是否能赢。两者分开调整。 | D16: 据点生命控制需要赢几轮；敌兵属性与编成控制某一轮是否能赢。两者分开调整。 | E16: 据点生命控制需要赢几轮；敌兵属性与编成控制某一轮是否能赢。两者分开调整。 | F16: 据点生命控制需要赢几轮；敌兵属性与编成控制某一轮是否能赢。两者分开调整。 | G16: 据点生命控制需要赢几轮；敌兵属性与编成控制某一轮是否能赢。两者分开调整。 | H16: 据点生命控制需要赢几轮；敌兵属性与编成控制某一轮是否能赢。两者分开调整。 | I16: 据点生命控制需要赢几轮；敌兵属性与编成控制某一轮是否能赢。两者分开调整。 | J16: 据点生命控制需要赢几轮；敌兵属性与编成控制某一轮是否能赢。两者分开调整。 | K16: 据点生命控制需要赢几轮；敌兵属性与编成控制某一轮是否能赢。两者分开调整。 | L16: 据点生命控制需要赢几轮；敌兵属性与编成控制某一轮是否能赢。两者分开调整。 | M16: 据点生命控制需要赢几轮；敌兵属性与编成控制某一轮是否能赢。两者分开调整。
A18: 路线预算（取回血选项；不使用药水） | B18: 路线预算（取回血选项；不使用药水） | C18: 路线预算（取回血选项；不使用药水） | D18: 路线预算（取回血选项；不使用药水） | E18: 路线预算（取回血选项；不使用药水）
A20: Boss最低入场生命 | C20: =IF(COUNT(路线生命!F9:F22)=14,MIN(路线生命!F9:F22),"待补脚本") -> 76
A21: Boss最高入场生命 | C21: =IF(COUNT(路线生命!F9:F22)=14,MAX(路线生命!F9:F22),"待补脚本") -> 100
A22: 章末最低生命 | C22: =IF(COUNT(路线生命!G9:G22)=14,MIN(路线生命!G9:G22),"待补脚本") -> 54
A23: 章末最高生命 | C23: =IF(COUNT(路线生命!G9:G22)=14,MAX(路线生命!G9:G22),"待补脚本") -> 78
A26: 先测A、E、F，再跑整章。每档至少10次，记录轮数、基地战损、剩余能量、征召当前费用；药水另列。 | B26: 先测A、E、F，再跑整章。每档至少10次，记录轮数、基地战损、剩余能量、征召当前费用；药水另列。 | C26: 先测A、E、F，再跑整章。每档至少10次，记录轮数、基地战损、剩余能量、征召当前费用；药水另列。 | D26: 先测A、E、F，再跑整章。每档至少10次，记录轮数、基地战损、剩余能量、征召当前费用；药水另列。 | E26: 先测A、E、F，再跑整章。每档至少10次，记录轮数、基地战损、剩余能量、征召当前费用；药水另列。
A27: 先测A、E、F，再跑整章。每档至少10次，记录轮数、基地战损、剩余能量、征召当前费用；药水另列。 | B27: 先测A、E、F，再跑整章。每档至少10次，记录轮数、基地战损、剩余能量、征召当前费用；药水另列。 | C27: 先测A、E、F，再跑整章。每档至少10次，记录轮数、基地战损、剩余能量、征召当前费用；药水另列。 | D27: 先测A、E、F，再跑整章。每档至少10次，记录轮数、基地战损、剩余能量、征召当前费用；药水另列。 | E27: 先测A、E、F，再跑整章。每档至少10次，记录轮数、基地战损、剩余能量、征召当前费用；药水另列。
A29: 若交锋本身合适但拖长，普通据点生命减4，Boss减6。若某一轮普遍全灭，先改编成或攻击，不先加回血。 | B29: 若交锋本身合适但拖长，普通据点生命减4，Boss减6。若某一轮普遍全灭，先改编成或攻击，不先加回血。 | C29: 若交锋本身合适但拖长，普通据点生命减4，Boss减6。若某一轮普遍全灭，先改编成或攻击，不先加回血。 | D29: 若交锋本身合适但拖长，普通据点生命减4，Boss减6。若某一轮普遍全灭，先改编成或攻击，不先加回血。 | E29: 若交锋本身合适但拖长，普通据点生命减4，Boss减6。若某一轮普遍全灭，先改编成或攻击，不先加回血。
A30: 若交锋本身合适但拖长，普通据点生命减4，Boss减6。若某一轮普遍全灭，先改编成或攻击，不先加回血。 | B30: 若交锋本身合适但拖长，普通据点生命减4，Boss减6。若某一轮普遍全灭，先改编成或攻击，不先加回血。 | C30: 若交锋本身合适但拖长，普通据点生命减4，Boss减6。若某一轮普遍全灭，先改编成或攻击，不先加回血。 | D30: 若交锋本身合适但拖长，普通据点生命减4，Boss减6。若某一轮普遍全灭，先改编成或攻击，不先加回血。 | E30: 若交锋本身合适但拖长，普通据点生命减4，Boss减6。若某一轮普遍全灭，先改编成或攻击，不先加回血。
A31: 若交锋本身合适但拖长，普通据点生命减4，Boss减6。若某一轮普遍全灭，先改编成或攻击，不先加回血。 | B31: 若交锋本身合适但拖长，普通据点生命减4，Boss减6。若某一轮普遍全灭，先改编成或攻击，不先加回血。 | C31: 若交锋本身合适但拖长，普通据点生命减4，Boss减6。若某一轮普遍全灭，先改编成或攻击，不先加回血。 | D31: 若交锋本身合适但拖长，普通据点生命减4，Boss减6。若某一轮普遍全灭，先改编成或攻击，不先加回血。 | E31: 若交锋本身合适但拖长，普通据点生命减4，Boss减6。若某一轮普遍全灭，先改编成或攻击，不先加回血。
A35: 编号 | B35: 据点生命 | C35: 参考战损
A36: A | B36: =D9 -> 22 | C36: =J9 -> 4
A37: B | B37: =D10 -> 30 | C37: =J10 -> 12
A38: C | B38: =D11 -> 34 | C38: =J11 -> 12
A39: D | B39: =D12 -> 38 | C39: =J12 -> 12
A40: E | B40: =D13 -> 42 | C40: =J13 -> 16
A41: F | B41: =D14 -> 52 | C41: =J14 -> 22
A44: 层 | B44: 实际战斗节点 | C44: 配置 | E44: 节点简写省略floor_。第3层全是事件；04_01、06_01是事件；09_02是休息。按实际type绑定。 | F44: 节点简写省略floor_。第3层全是事件；04_01、06_01是事件；09_02是休息。按实际type绑定。 | G44: 节点简写省略floor_。第3层全是事件；04_01、06_01是事件；09_02是休息。按实际type绑定。 | H44: 节点简写省略floor_。第3层全是事件；04_01、06_01是事件；09_02是休息。按实际type绑定。 | I44: 节点简写省略floor_。第3层全是事件；04_01、06_01是事件；09_02是休息。按实际type绑定。 | J44: 节点简写省略floor_。第3层全是事件；04_01、06_01是事件；09_02是休息。按实际type绑定。 | K44: 节点简写省略floor_。第3层全是事件；04_01、06_01是事件；09_02是休息。按实际type绑定。 | L44: 节点简写省略floor_。第3层全是事件；04_01、06_01是事件；09_02是休息。按实际type绑定。 | M44: 节点简写省略floor_。第3层全是事件；04_01、06_01是事件；09_02是休息。按实际type绑定。
A45: 2 | B45: 02_01 / 02_02 / 02_03 | C45: A | E45: 节点简写省略floor_。第3层全是事件；04_01、06_01是事件；09_02是休息。按实际type绑定。 | F45: 节点简写省略floor_。第3层全是事件；04_01、06_01是事件；09_02是休息。按实际type绑定。 | G45: 节点简写省略floor_。第3层全是事件；04_01、06_01是事件；09_02是休息。按实际type绑定。 | H45: 节点简写省略floor_。第3层全是事件；04_01、06_01是事件；09_02是休息。按实际type绑定。 | I45: 节点简写省略floor_。第3层全是事件；04_01、06_01是事件；09_02是休息。按实际type绑定。 | J45: 节点简写省略floor_。第3层全是事件；04_01、06_01是事件；09_02是休息。按实际type绑定。 | K45: 节点简写省略floor_。第3层全是事件；04_01、06_01是事件；09_02是休息。按实际type绑定。 | L45: 节点简写省略floor_。第3层全是事件；04_01、06_01是事件；09_02是休息。按实际type绑定。 | M45: 节点简写省略floor_。第3层全是事件；04_01、06_01是事件；09_02是休息。按实际type绑定。
A46: 4 | B46: 04_03 | C46: B | E46: 节点简写省略floor_。第3层全是事件；04_01、06_01是事件；09_02是休息。按实际type绑定。 | F46: 节点简写省略floor_。第3层全是事件；04_01、06_01是事件；09_02是休息。按实际type绑定。 | G46: 节点简写省略floor_。第3层全是事件；04_01、06_01是事件；09_02是休息。按实际type绑定。 | H46: 节点简写省略floor_。第3层全是事件；04_01、06_01是事件；09_02是休息。按实际type绑定。 | I46: 节点简写省略floor_。第3层全是事件；04_01、06_01是事件；09_02是休息。按实际type绑定。 | J46: 节点简写省略floor_。第3层全是事件；04_01、06_01是事件；09_02是休息。按实际type绑定。 | K46: 节点简写省略floor_。第3层全是事件；04_01、06_01是事件；09_02是休息。按实际type绑定。 | L46: 节点简写省略floor_。第3层全是事件；04_01、06_01是事件；09_02是休息。按实际type绑定。 | M46: 节点简写省略floor_。第3层全是事件；04_01、06_01是事件；09_02是休息。按实际type绑定。
A47: 5 | B47: 05_02 | C47: C
A48: 7 | B48: 07_02 / 07_03 | C48: D | E48: 源：当前章节JSON、BattleLevelConfig及战斗/卡牌脚本。完整字段、源文件和填表步骤见同目录初版文档。 | F48: 源：当前章节JSON、BattleLevelConfig及战斗/卡牌脚本。完整字段、源文件和填表步骤见同目录初版文档。 | G48: 源：当前章节JSON、BattleLevelConfig及战斗/卡牌脚本。完整字段、源文件和填表步骤见同目录初版文档。 | H48: 源：当前章节JSON、BattleLevelConfig及战斗/卡牌脚本。完整字段、源文件和填表步骤见同目录初版文档。 | I48: 源：当前章节JSON、BattleLevelConfig及战斗/卡牌脚本。完整字段、源文件和填表步骤见同目录初版文档。 | J48: 源：当前章节JSON、BattleLevelConfig及战斗/卡牌脚本。完整字段、源文件和填表步骤见同目录初版文档。 | K48: 源：当前章节JSON、BattleLevelConfig及战斗/卡牌脚本。完整字段、源文件和填表步骤见同目录初版文档。 | L48: 源：当前章节JSON、BattleLevelConfig及战斗/卡牌脚本。完整字段、源文件和填表步骤见同目录初版文档。 | M48: 源：当前章节JSON、BattleLevelConfig及战斗/卡牌脚本。完整字段、源文件和填表步骤见同目录初版文档。
A49: 8 | B49: 08_01 / 08_03 | C49: E | E49: 源：当前章节JSON、BattleLevelConfig及战斗/卡牌脚本。完整字段、源文件和填表步骤见同目录初版文档。 | F49: 源：当前章节JSON、BattleLevelConfig及战斗/卡牌脚本。完整字段、源文件和填表步骤见同目录初版文档。 | G49: 源：当前章节JSON、BattleLevelConfig及战斗/卡牌脚本。完整字段、源文件和填表步骤见同目录初版文档。 | H49: 源：当前章节JSON、BattleLevelConfig及战斗/卡牌脚本。完整字段、源文件和填表步骤见同目录初版文档。 | I49: 源：当前章节JSON、BattleLevelConfig及战斗/卡牌脚本。完整字段、源文件和填表步骤见同目录初版文档。 | J49: 源：当前章节JSON、BattleLevelConfig及战斗/卡牌脚本。完整字段、源文件和填表步骤见同目录初版文档。 | K49: 源：当前章节JSON、BattleLevelConfig及战斗/卡牌脚本。完整字段、源文件和填表步骤见同目录初版文档。 | L49: 源：当前章节JSON、BattleLevelConfig及战斗/卡牌脚本。完整字段、源文件和填表步骤见同目录初版文档。 | M49: 源：当前章节JSON、BattleLevelConfig及战斗/卡牌脚本。完整字段、源文件和填表步骤见同目录初版文档。
A50: 10 | B50: 10_01 | C50: F | E50: 源：当前章节JSON、BattleLevelConfig及战斗/卡牌脚本。完整字段、源文件和填表步骤见同目录初版文档。 | F50: 源：当前章节JSON、BattleLevelConfig及战斗/卡牌脚本。完整字段、源文件和填表步骤见同目录初版文档。 | G50: 源：当前章节JSON、BattleLevelConfig及战斗/卡牌脚本。完整字段、源文件和填表步骤见同目录初版文档。 | H50: 源：当前章节JSON、BattleLevelConfig及战斗/卡牌脚本。完整字段、源文件和填表步骤见同目录初版文档。 | I50: 源：当前章节JSON、BattleLevelConfig及战斗/卡牌脚本。完整字段、源文件和填表步骤见同目录初版文档。 | J50: 源：当前章节JSON、BattleLevelConfig及战斗/卡牌脚本。完整字段、源文件和填表步骤见同目录初版文档。 | K50: 源：当前章节JSON、BattleLevelConfig及战斗/卡牌脚本。完整字段、源文件和填表步骤见同目录初版文档。 | L50: 源：当前章节JSON、BattleLevelConfig及战斗/卡牌脚本。完整字段、源文件和填表步骤见同目录初版文档。 | M50: 源：当前章节JSON、BattleLevelConfig及战斗/卡牌脚本。完整字段、源文件和填表步骤见同目录初版文档。

Sheet 路线生命
A2: 14条实际路线的生命预算 | B2: 14条实际路线的生命预算 | C2: 14条实际路线的生命预算 | D2: 14条实际路线的生命预算 | E2: 14条实际路线的生命预算 | F2: 14条实际路线的生命预算 | G2: 14条实际路线的生命预算 | H2: 14条实际路线的生命预算 | I2: 14条实际路线的生命预算 | J2: 14条实际路线的生命预算 | K2: 14条实际路线的生命预算 | L2: 14条实际路线的生命预算 | M2: 14条实际路线的生命预算 | N2: 14条实际路线的生命预算 | O2: 14条实际路线的生命预算 | P2: 14条实际路线的生命预算 | Q2: 14条实际路线的生命预算 | R2: 14条实际路线的生命预算 | S2: 14条实际路线的生命预算 | T2: 14条实际路线的生命预算 | U2: 14条实际路线的生命预算 | V2: 14条实际路线的生命预算 | W2: 14条实际路线的生命预算 | X2: 14条实际路线的生命预算 | Y2: 14条实际路线的生命预算 | Z2: 14条实际路线的生命预算 | AA2: 14条实际路线的生命预算 | AB2: 14条实际路线的生命预算 | AC2: 14条实际路线的生命预算 | AD2: 14条实际路线的生命预算 | AE2: 14条实际路线的生命预算
A4: 按真实节点类型，取回血选项，满血溢出不计回复。战损倍率只放大预算，不模拟另一组交锋；死亡后生命保持0。 | B4: 按真实节点类型，取回血选项，满血溢出不计回复。战损倍率只放大预算，不模拟另一组交锋；死亡后生命保持0。 | C4: 按真实节点类型，取回血选项，满血溢出不计回复。战损倍率只放大预算，不模拟另一组交锋；死亡后生命保持0。 | D4: 按真实节点类型，取回血选项，满血溢出不计回复。战损倍率只放大预算，不模拟另一组交锋；死亡后生命保持0。 | E4: 按真实节点类型，取回血选项，满血溢出不计回复。战损倍率只放大预算，不模拟另一组交锋；死亡后生命保持0。 | F4: 按真实节点类型，取回血选项，满血溢出不计回复。战损倍率只放大预算，不模拟另一组交锋；死亡后生命保持0。 | G4: 按真实节点类型，取回血选项，满血溢出不计回复。战损倍率只放大预算，不模拟另一组交锋；死亡后生命保持0。 | H4: 按真实节点类型，取回血选项，满血溢出不计回复。战损倍率只放大预算，不模拟另一组交锋；死亡后生命保持0。 | I4: 按真实节点类型，取回血选项，满血溢出不计回复。战损倍率只放大预算，不模拟另一组交锋；死亡后生命保持0。 | J4: 按真实节点类型，取回血选项，满血溢出不计回复。战损倍率只放大预算，不模拟另一组交锋；死亡后生命保持0。 | K4: 按真实节点类型，取回血选项，满血溢出不计回复。战损倍率只放大预算，不模拟另一组交锋；死亡后生命保持0。 | L4: 按真实节点类型，取回血选项，满血溢出不计回复。战损倍率只放大预算，不模拟另一组交锋；死亡后生命保持0。 | M4: 按真实节点类型，取回血选项，满血溢出不计回复。战损倍率只放大预算，不模拟另一组交锋；死亡后生命保持0。 | N4: 按真实节点类型，取回血选项，满血溢出不计回复。战损倍率只放大预算，不模拟另一组交锋；死亡后生命保持0。 | O4: 按真实节点类型，取回血选项，满血溢出不计回复。战损倍率只放大预算，不模拟另一组交锋；死亡后生命保持0。 | P4: 按真实节点类型，取回血选项，满血溢出不计回复。战损倍率只放大预算，不模拟另一组交锋；死亡后生命保持0。 | Q4: 按真实节点类型，取回血选项，满血溢出不计回复。战损倍率只放大预算，不模拟另一组交锋；死亡后生命保持0。 | R4: 按真实节点类型，取回血选项，满血溢出不计回复。战损倍率只放大预算，不模拟另一组交锋；死亡后生命保持0。 | S4: 按真实节点类型，取回血选项，满血溢出不计回复。战损倍率只放大预算，不模拟另一组交锋；死亡后生命保持0。 | T4: 按真实节点类型，取回血选项，满血溢出不计回复。战损倍率只放大预算，不模拟另一组交锋；死亡后生命保持0。 | U4: 按真实节点类型，取回血选项，满血溢出不计回复。战损倍率只放大预算，不模拟另一组交锋；死亡后生命保持0。 | V4: 按真实节点类型，取回血选项，满血溢出不计回复。战损倍率只放大预算，不模拟另一组交锋；死亡后生命保持0。 | W4: 按真实节点类型，取回血选项，满血溢出不计回复。战损倍率只放大预算，不模拟另一组交锋；死亡后生命保持0。 | X4: 按真实节点类型，取回血选项，满血溢出不计回复。战损倍率只放大预算，不模拟另一组交锋；死亡后生命保持0。 | Y4: 按真实节点类型，取回血选项，满血溢出不计回复。战损倍率只放大预算，不模拟另一组交锋；死亡后生命保持0。 | Z4: 按真实节点类型，取回血选项，满血溢出不计回复。战损倍率只放大预算，不模拟另一组交锋；死亡后生命保持0。 | AA4: 按真实节点类型，取回血选项，满血溢出不计回复。战损倍率只放大预算，不模拟另一组交锋；死亡后生命保持0。 | AB4: 按真实节点类型，取回血选项，满血溢出不计回复。战损倍率只放大预算，不模拟另一组交锋；死亡后生命保持0。 | AC4: 按真实节点类型，取回血选项，满血溢出不计回复。战损倍率只放大预算，不模拟另一组交锋；死亡后生命保持0。 | AD4: 按真实节点类型，取回血选项，满血溢出不计回复。战损倍率只放大预算，不模拟另一组交锋；死亡后生命保持0。 | AE4: 按真实节点类型，取回血选项，满血溢出不计回复。战损倍率只放大预算，不模拟另一组交锋；死亡后生命保持0。
A5: 开局生命 | B5: 100 | C5: 生命上限 | D5: 100 | E5: 战损倍率 | F5: 1
A6: 可将F5改为1.5观察压力预算。若某套据点未扣完，路线结果显示待补脚本。右侧保留逐层生命与实际回复。 | B6: 可将F5改为1.5观察压力预算。若某套据点未扣完，路线结果显示待补脚本。右侧保留逐层生命与实际回复。 | C6: 可将F5改为1.5观察压力预算。若某套据点未扣完，路线结果显示待补脚本。右侧保留逐层生命与实际回复。 | D6: 可将F5改为1.5观察压力预算。若某套据点未扣完，路线结果显示待补脚本。右侧保留逐层生命与实际回复。 | E6: 可将F5改为1.5观察压力预算。若某套据点未扣完，路线结果显示待补脚本。右侧保留逐层生命与实际回复。 | F6: 可将F5改为1.5观察压力预算。若某套据点未扣完，路线结果显示待补脚本。右侧保留逐层生命与实际回复。 | G6: 可将F5改为1.5观察压力预算。若某套据点未扣完，路线结果显示待补脚本。右侧保留逐层生命与实际回复。 | H6: 可将F5改为1.5观察压力预算。若某套据点未扣完，路线结果显示待补脚本。右侧保留逐层生命与实际回复。
A8: 路径 | B8: 节点序列（省略floor_） | C8: 普通场数 | D8: 战损预算 | E8: 实际回复 | F8: Boss入场 | G8: 章末生命 | H8: 脚本状态 | J8: 出发 | K8: 层1后 | L8: 层2后 | M8: 层3后 | N8: 层4后 | O8: 层5后 | P8: 层6后 | Q8: 层7后 | R8: 层8后 | S8: 层9后 | T8: 层10后 | V8: 层1回复 | W8: 层2回复 | X8: 层3回复 | Y8: 层4回复 | Z8: 层5回复 | AA8: 层6回复 | AB8: 层7回复 | AC8: 层8回复 | AD8: 层9回复 | AE8: 层10回复
A9: 1 | B9: 02_02 → 03_02 → 04_01 → 05_01 → 06_01 → 07_01 → 08_01 → 09_01 | C9: 2 | D9: =IF(OR(关卡总览!$K$9<>"已扣完",关卡总览!$K$13<>"已扣完",关卡总览!$K$14<>"已扣完"),"待补脚本",关卡总览!$J$9*$F$5+关卡总览!$J$13*$F$5+关卡总览!$J$14*$F$5) -> 42 | E9: =IF(OR(关卡总览!$K$9<>"已扣完",关卡总览!$K$13<>"已扣完",关卡总览!$K$14<>"已扣完"),"待补脚本",SUM(V9:AE9)) -> 20 | F9: =IF(OR(关卡总览!$K$9<>"已扣完",关卡总览!$K$13<>"已扣完",关卡总览!$K$14<>"已扣完"),"待补脚本",S9) -> 100 | G9: =IF(OR(关卡总览!$K$9<>"已扣完",关卡总览!$K$13<>"已扣完",关卡总览!$K$14<>"已扣完"),"待补脚本",T9) -> 78 | H9: =IF(OR(关卡总览!$K$9<>"已扣完",关卡总览!$K$13<>"已扣完",关卡总览!$K$14<>"已扣完"),"待补脚本",IF(T9<=0,"预算耗尽","有余量")) -> 有余量 | J9: =$B$5 -> 100 | K9: =IF(OR(J9<=0,J9-0<=0),0,MIN($D$5,J9-0+0)) -> 100 | L9: =IF(OR(K9<=0,K9-关卡总览!$J$9*$F$5<=0),0,MIN($D$5,K9-关卡总览!$J$9*$F$5+0)) -> 96 | M9: =IF(OR(L9<=0,L9-0<=0),0,MIN($D$5,L9-0+0)) -> 96 | N9: =IF(OR(M9<=0,M9-0<=0),0,MIN($D$5,M9-0+0)) -> 96 | O9: =IF(OR(N9<=0,N9-0<=0),0,MIN($D$5,N9-0+0)) -> 96 | P9: =IF(OR(O9<=0,O9-0<=0),0,MIN($D$5,O9-0+0)) -> 96 | Q9: =IF(OR(P9<=0,P9-0<=0),0,MIN($D$5,P9-0+0)) -> 96 | R9: =IF(OR(Q9<=0,Q9-关卡总览!$J$13*$F$5<=0),0,MIN($D$5,Q9-关卡总览!$J$13*$F$5+0)) -> 80 | S9: =IF(OR(R9<=0,R9-0<=0),0,MIN($D$5,R9-0+20)) -> 100 | T9: =IF(OR(S9<=0,S9-关卡总览!$J$14*$F$5<=0),0,MIN($D$5,S9-关卡总览!$J$14*$F$5+0)) -> 78 | V9: =IF(J9>0,MIN(MAX(0,$D$5-(J9-0)),0),0) -> 0 | W9: =IF(K9>关卡总览!$J$9*$F$5,MIN(MAX(0,$D$5-(K9-关卡总览!$J$9*$F$5)),0),0) -> 0 | X9: =IF(L9>0,MIN(MAX(0,$D$5-(L9-0)),0),0) -> 0 | Y9: =IF(M9>0,MIN(MAX(0,$D$5-(M9-0)),0),0) -> 0 | Z9: =IF(N9>0,MIN(MAX(0,$D$5-(N9-0)),0),0) -> 0 | AA9: =IF(O9>0,MIN(MAX(0,$D$5-(O9-0)),0),0) -> 0 | AB9: =IF(P9>0,MIN(MAX(0,$D$5-(P9-0)),0),0) -> 0 | AC9: =IF(Q9>关卡总览!$J$13*$F$5,MIN(MAX(0,$D$5-(Q9-关卡总览!$J$13*$F$5)),0),0) -> 0 | AD9: =IF(R9>0,MIN(MAX(0,$D$5-(R9-0)),20),0) -> 20 | AE9: =IF(S9>关卡总览!$J$14*$F$5,MIN(MAX(0,$D$5-(S9-关卡总览!$J$14*$F$5)),0),0) -> 0
A10: 2 | B10: 02_02 → 03_02 → 04_01 → 05_01 → 06_01 → 07_02 → 08_01 → 09_01 | C10: 3 | D10: =IF(OR(关卡总览!$K$9<>"已扣完",关卡总览!$K$12<>"已扣完",关卡总览!$K$13<>"已扣完",关卡总览!$K$14<>"已扣完"),"待补脚本",关卡总览!$J$9*$F$5+关卡总览!$J$12*$F$5+关卡总览!$J$13*$F$5+关卡总览!$J$14*$F$5) -> 54 | E10: =IF(OR(关卡总览!$K$9<>"已扣完",关卡总览!$K$12<>"已扣完",关卡总览!$K$13<>"已扣完",关卡总览!$K$14<>"已扣完"),"待补脚本",SUM(V10:AE10)) -> 20 | F10: =IF(OR(关卡总览!$K$9<>"已扣完",关卡总览!$K$12<>"已扣完",关卡总览!$K$13<>"已扣完",关卡总览!$K$14<>"已扣完"),"待补脚本",S10) -> 88 | G10: =IF(OR(关卡总览!$K$9<>"已扣完",关卡总览!$K$12<>"已扣完",关卡总览!$K$13<>"已扣完",关卡总览!$K$14<>"已扣完"),"待补脚本",T10) -> 66 | H10: =IF(OR(关卡总览!$K$9<>"已扣完",关卡总览!$K$12<>"已扣完",关卡总览!$K$13<>"已扣完",关卡总览!$K$14<>"已扣完"),"待补脚本",IF(T10<=0,"预算耗尽","有余量")) -> 有余量 | J10: =$B$5 -> 100 | K10: =IF(OR(J10<=0,J10-0<=0),0,MIN($D$5,J10-0+0)) -> 100 | L10: =IF(OR(K10<=0,K10-关卡总览!$J$9*$F$5<=0),0,MIN($D$5,K10-关卡总览!$J$9*$F$5+0)) -> 96 | M10: =IF(OR(L10<=0,L10-0<=0),0,MIN($D$5,L10-0+0)) -> 96 | N10: =IF(OR(M10<=0,M10-0<=0),0,MIN($D$5,M10-0+0)) -> 96 | O10: =IF(OR(N10<=0,N10-0<=0),0,MIN($D$5,N10-0+0)) -> 96 | P10: =IF(OR(O10<=0,O10-0<=0),0,MIN($D$5,O10-0+0)) -> 96 | Q10: =IF(OR(P10<=0,P10-关卡总览!$J$12*$F$5<=0),0,MIN($D$5,P10-关卡总览!$J$12*$F$5+0)) -> 84 | R10: =IF(OR(Q10<=0,Q10-关卡总览!$J$13*$F$5<=0),0,MIN($D$5,Q10-关卡总览!$J$13*$F$5+0)) -> 68 | S10: =IF(OR(R10<=0,R10-0<=0),0,MIN($D$5,R10-0+20)) -> 88 | T10: =IF(OR(S10<=0,S10-关卡总览!$J$14*$F$5<=0),0,MIN($D$5,S10-关卡总览!$J$14*$F$5+0)) -> 66 | V10: =IF(J10>0,MIN(MAX(0,$D$5-(J10-0)),0),0) -> 0 | W10: =IF(K10>关卡总览!$J$9*$F$5,MIN(MAX(0,$D$5-(K10-关卡总览!$J$9*$F$5)),0),0) -> 0 | X10: =IF(L10>0,MIN(MAX(0,$D$5-(L10-0)),0),0) -> 0 | Y10: =IF(M10>0,MIN(MAX(0,$D$5-(M10-0)),0),0) -> 0 | Z10: =IF(N10>0,MIN(MAX(0,$D$5-(N10-0)),0),0) -> 0 | AA10: =IF(O10>0,MIN(MAX(0,$D$5-(O10-0)),0),0) -> 0 | AB10: =IF(P10>关卡总览!$J$12*$F$5,MIN(MAX(0,$D$5-(P10-关卡总览!$J$12*$F$5)),0),0) -> 0 | AC10: =IF(Q10>关卡总览!$J$13*$F$5,MIN(MAX(0,$D$5-(Q10-关卡总览!$J$13*$F$5)),0),0) -> 0 | AD10: =IF(R10>0,MIN(MAX(0,$D$5-(R10-0)),20),0) -> 20 | AE10: =IF(S10>关卡总览!$J$14*$F$5,MIN(MAX(0,$D$5-(S10-关卡总览!$J$14*$F$5)),0),0) -> 0
A11: 3 | B11: 02_02 → 03_03 → 04_02 → 05_03 → 06_03 → 07_03 → 08_02 → 09_02 | C11: 2 | D11: =IF(OR(关卡总览!$K$9<>"已扣完",关卡总览!$K$12<>"已扣完",关卡总览!$K$14<>"已扣完"),"待补脚本",关卡总览!$J$9*$F$5+关卡总览!$J$12*$F$5+关卡总览!$J$14*$F$5) -> 38 | E11: =IF(OR(关卡总览!$K$9<>"已扣完",关卡总览!$K$12<>"已扣完",关卡总览!$K$14<>"已扣完"),"待补脚本",SUM(V11:AE11)) -> 16 | F11: =IF(OR(关卡总览!$K$9<>"已扣完",关卡总览!$K$12<>"已扣完",关卡总览!$K$14<>"已扣完"),"待补脚本",S11) -> 100 | G11: =IF(OR(关卡总览!$K$9<>"已扣完",关卡总览!$K$12<>"已扣完",关卡总览!$K$14<>"已扣完"),"待补脚本",T11) -> 78 | H11: =IF(OR(关卡总览!$K$9<>"已扣完",关卡总览!$K$12<>"已扣完",关卡总览!$K$14<>"已扣完"),"待补脚本",IF(T11<=0,"预算耗尽","有余量")) -> 有余量 | J11: =$B$5 -> 100 | K11: =IF(OR(J11<=0,J11-0<=0),0,MIN($D$5,J11-0+0)) -> 100 | L11: =IF(OR(K11<=0,K11-关卡总览!$J$9*$F$5<=0),0,MIN($D$5,K11-关卡总览!$J$9*$F$5+0)) -> 96 | M11: =IF(OR(L11<=0,L11-0<=0),0,MIN($D$5,L11-0+0)) -> 96 | N11: =IF(OR(M11<=0,M11-0<=0),0,MIN($D$5,M11-0+20)) -> 100 | O11: =IF(OR(N11<=0,N11-0<=0),0,MIN($D$5,N11-0+0)) -> 100 | P11: =IF(OR(O11<=0,O11-0<=0),0,MIN($D$5,O11-0+0)) -> 100 | Q11: =IF(OR(P11<=0,P11-关卡总览!$J$12*$F$5<=0),0,MIN($D$5,P11-关卡总览!$J$12*$F$5+0)) -> 88 | R11: =IF(OR(Q11<=0,Q11-0<=0),0,MIN($D$5,Q11-0+0)) -> 88 | S11: =IF(OR(R11<=0,R11-0<=0),0,MIN($D$5,R11-0+20)) -> 100 | T11: =IF(OR(S11<=0,S11-关卡总览!$J$14*$F$5<=0),0,MIN($D$5,S11-关卡总览!$J$14*$F$5+0)) -> 78 | V11: =IF(J11>0,MIN(MAX(0,$D$5-(J11-0)),0),0) -> 0 | W11: =IF(K11>关卡总览!$J$9*$F$5,MIN(MAX(0,$D$5-(K11-关卡总览!$J$9*$F$5)),0),0) -> 0 | X11: =IF(L11>0,MIN(MAX(0,$D$5-(L11-0)),0),0) -> 0 | Y11: =IF(M11>0,MIN(MAX(0,$D$5-(M11-0)),20),0) -> 4 | Z11: =IF(N11>0,MIN(MAX(0,$D$5-(N11-0)),0),0) -> 0 | AA11: =IF(O11>0,MIN(MAX(0,$D$5-(O11-0)),0),0) -> 0 | AB11: =IF(P11>关卡总览!$J$12*$F$5,MIN(MAX(0,$D$5-(P11-关卡总览!$J$12*$F$5)),0),0) -> 0 | AC11: =IF(Q11>0,MIN(MAX(0,$D$5-(Q11-0)),0),0) -> 0 | AD11: =IF(R11>0,MIN(MAX(0,$D$5-(R11-0)),20),0) -> 12 | AE11: =IF(S11>关卡总览!$J$14*$F$5,MIN(MAX(0,$D$5-(S11-关卡总览!$J$14*$F$5)),0),0) -> 0
A12: 4 | B12: 02_02 → 03_03 → 04_02 → 05_03 → 06_03 → 07_03 → 08_03 → 09_02 | C12: 3 | D12: =IF(OR(关卡总览!$K$9<>"已扣完",关卡总览!$K$12<>"已扣完",关卡总览!$K$13<>"已扣完",关卡总览!$K$14<>"已扣完"),"待补脚本",关卡总览!$J$9*$F$5+关卡总览!$J$12*$F$5+关卡总览!$J$13*$F$5+关卡总览!$J$14*$F$5) -> 54 | E12: =IF(OR(关卡总览!$K$9<>"已扣完",关卡总览!$K$12<>"已扣完",关卡总览!$K$13<>"已扣完",关卡总览!$K$14<>"已扣完"),"待补脚本",SUM(V12:AE12)) -> 24 | F12: =IF(OR(关卡总览!$K$9<>"已扣完",关卡总览!$K$12<>"已扣完",关卡总览!$K$13<>"已扣完",关卡总览!$K$14<>"已扣完"),"待补脚本",S12) -> 92 | G12: =IF(OR(关卡总览!$K$9<>"已扣完",关卡总览!$K$12<>"已扣完",关卡总览!$K$13<>"已扣完",关卡总览!$K$14<>"已扣完"),"待补脚本",T12) -> 70 | H12: =IF(OR(关卡总览!$K$9<>"已扣完",关卡总览!$K$12<>"已扣完",关卡总览!$K$13<>"已扣完",关卡总览!$K$14<>"已扣完"),"待补脚本",IF(T12<=0,"预算耗尽","有余量")) -> 有余量 | J12: =$B$5 -> 100 | K12: =IF(OR(J12<=0,J12-0<=0),0,MIN($D$5,J12-0+0)) -> 100 | L12: =IF(OR(K12<=0,K12-关卡总览!$J$9*$F$5<=0),0,MIN($D$5,K12-关卡总览!$J$9*$F$5+0)) -> 96 | M12: =IF(OR(L12<=0,L12-0<=0),0,MIN($D$5,L12-0+0)) -> 96 | N12: =IF(OR(M12<=0,M12-0<=0),0,MIN($D$5,M12-0+20)) -> 100 | O12: =IF(OR(N12<=0,N12-0<=0),0,MIN($D$5,N12-0+0)) -> 100 | P12: =IF(OR(O12<=0,O12-0<=0),0,MIN($D$5,O12-0+0)) -> 100 | Q12: =IF(OR(P12<=0,P12-关卡总览!$J$12*$F$5<=0),0,MIN($D$5,P12-关卡总览!$J$12*$F$5+0)) -> 88 | R12: =IF(OR(Q12<=0,Q12-关卡总览!$J$13*$F$5<=0),0,MIN($D$5,Q12-关卡总览!$J$13*$F$5+0)) -> 72 | S12: =IF(OR(R12<=0,R12-0<=0),0,MIN($D$5,R12-0+20)) -> 92 | T12: =IF(OR(S12<=0,S12-关卡总览!$J$14*$F$5<=0),0,MIN($D$5,S12-关卡总览!$J$14*$F$5+0)) -> 70 | V12: =IF(J12>0,MIN(MAX(0,$D$5-(J12-0)),0),0) -> 0 | W12: =IF(K12>关卡总览!$J$9*$F$5,MIN(MAX(0,$D$5-(K12-关卡总览!$J$9*$F$5)),0),0) -> 0 | X12: =IF(L12>0,MIN(MAX(0,$D$5-(L12-0)),0),0) -> 0 | Y12: =IF(M12>0,MIN(MAX(0,$D$5-(M12-0)),20),0) -> 4 | Z12: =IF(N12>0,MIN(MAX(0,$D$5-(N12-0)),0),0) -> 0 | AA12: =IF(O12>0,MIN(MAX(0,$D$5-(O12-0)),0),0) -> 0 | AB12: =IF(P12>关卡总览!$J$12*$F$5,MIN(MAX(0,$D$5-(P12-关卡总览!$J$12*$F$5)),0),0) -> 0 | AC12: =IF(Q12>关卡总览!$J$13*$F$5,MIN(MAX(0,$D$5-(Q12-关卡总览!$J$13*$F$5)),0),0) -> 0 | AD12: =IF(R12>0,MIN(MAX(0,$D$5-(R12-0)),20),0) -> 20 | AE12: =IF(S12>关卡总览!$J$14*$F$5,MIN(MAX(0,$D$5-(S12-关卡总览!$J$14*$F$5)),0),0) -> 0
A13: 5 | B13: 02_02 → 03_03 → 04_02 → 05_03 → 06_02 → 07_03 → 08_02 → 09_02 | C13: 2 | D13: =IF(OR(关卡总览!$K$9<>"已扣完",关卡总览!$K$12<>"已扣完",关卡总览!$K$14<>"已扣完"),"待补脚本",关卡总览!$J$9*$F$5+关卡总览!$J$12*$F$5+关卡总览!$J$14*$F$5) -> 38 | E13: =IF(OR(关卡总览!$K$9<>"已扣完",关卡总览!$K$12<>"已扣完",关卡总览!$K$14<>"已扣完"),"待补脚本",SUM(V13:AE13)) -> 16 | F13: =IF(OR(关卡总览!$K$9<>"已扣完",关卡总览!$K$12<>"已扣完",关卡总览!$K$14<>"已扣完"),"待补脚本",S13) -> 100 | G13: =IF(OR(关卡总览!$K$9<>"已扣完",关卡总览!$K$12<>"已扣完",关卡总览!$K$14<>"已扣完"),"待补脚本",T13) -> 78 | H13: =IF(OR(关卡总览!$K$9<>"已扣完",关卡总览!$K$12<>"已扣完",关卡总览!$K$14<>"已扣完"),"待补脚本",IF(T13<=0,"预算耗尽","有余量")) -> 有余量 | J13: =$B$5 -> 100 | K13: =IF(OR(J13<=0,J13-0<=0),0,MIN($D$5,J13-0+0)) -> 100 | L13: =IF(OR(K13<=0,K13-关卡总览!$J$9*$F$5<=0),0,MIN($D$5,K13-关卡总览!$J$9*$F$5+0)) -> 96 | M13: =IF(OR(L13<=0,L13-0<=0),0,MIN($D$5,L13-0+0)) -> 96 | N13: =IF(OR(M13<=0,M13-0<=0),0,MIN($D$5,M13-0+20)) -> 100 | O13: =IF(OR(N13<=0,N13-0<=0),0,MIN($D$5,N13-0+0)) -> 100 | P13: =IF(OR(O13<=0,O13-0<=0),0,MIN($D$5,O13-0+20)) -> 100 | Q13: =IF(OR(P13<=0,P13-关卡总览!$J$12*$F$5<=0),0,MIN($D$5,P13-关卡总览!$J$12*$F$5+0)) -> 88 | R13: =IF(OR(Q13<=0,Q13-0<=0),0,MIN($D$5,Q13-0+0)) -> 88 | S13: =IF(OR(R13<=0,R13-0<=0),0,MIN($D$5,R13-0+20)) -> 100 | T13: =IF(OR(S13<=0,S13-关卡总览!$J$14*$F$5<=0),0,MIN($D$5,S13-关卡总览!$J$14*$F$5+0)) -> 78 | V13: =IF(J13>0,MIN(MAX(0,$D$5-(J13-0)),0),0) -> 0 | W13: =IF(K13>关卡总览!$J$9*$F$5,MIN(MAX(0,$D$5-(K13-关卡总览!$J$9*$F$5)),0),0) -> 0 | X13: =IF(L13>0,MIN(MAX(0,$D$5-(L13-0)),0),0) -> 0 | Y13: =IF(M13>0,MIN(MAX(0,$D$5-(M13-0)),20),0) -> 4 | Z13: =IF(N13>0,MIN(MAX(0,$D$5-(N13-0)),0),0) -> 0 | AA13: =IF(O13>0,MIN(MAX(0,$D$5-(O13-0)),20),0) -> 0 | AB13: =IF(P13>关卡总览!$J$12*$F$5,MIN(MAX(0,$D$5-(P13-关卡总览!$J$12*$F$5)),0),0) -> 0 | AC13: =IF(Q13>0,MIN(MAX(0,$D$5-(Q13-0)),0),0) -> 0 | AD13: =IF(R13>0,MIN(MAX(0,$D$5-(R13-0)),20),0) -> 12 | AE13: =IF(S13>关卡总览!$J$14*$F$5,MIN(MAX(0,$D$5-(S13-关卡总览!$J$14*$F$5)),0),0) -> 0
A14: 6 | B14: 02_02 → 03_03 → 04_02 → 05_03 → 06_02 → 07_03 → 08_03 → 09_02 | C14: 3 | D14: =IF(OR(关卡总览!$K$9<>"已扣完",关卡总览!$K$12<>"已扣完",关卡总览!$K$13<>"已扣完",关卡总览!$K$14<>"已扣完"),"待补脚本",关卡总览!$J$9*$F$5+关卡总览!$J$12*$F$5+关卡总览!$J$13*$F$5+关卡总览!$J$14*$F$5) -> 54 | E14: =IF(OR(关卡总览!$K$9<>"已扣完",关卡总览!$K$12<>"已扣完",关卡总览!$K$13<>"已扣完",关卡总览!$K$14<>"已扣完"),"待补脚本",SUM(V14:AE14)) -> 24 | F14: =IF(OR(关卡总览!$K$9<>"已扣完",关卡总览!$K$12<>"已扣完",关卡总览!$K$13<>"已扣完",关卡总览!$K$14<>"已扣完"),"待补脚本",S14) -> 92 | G14: =IF(OR(关卡总览!$K$9<>"已扣完",关卡总览!$K$12<>"已扣完",关卡总览!$K$13<>"已扣完",关卡总览!$K$14<>"已扣完"),"待补脚本",T14) -> 70 | H14: =IF(OR(关卡总览!$K$9<>"已扣完",关卡总览!$K$12<>"已扣完",关卡总览!$K$13<>"已扣完",关卡总览!$K$14<>"已扣完"),"待补脚本",IF(T14<=0,"预算耗尽","有余量")) -> 有余量 | J14: =$B$5 -> 100 | K14: =IF(OR(J14<=0,J14-0<=0),0,MIN($D$5,J14-0+0)) -> 100 | L14: =IF(OR(K14<=0,K14-关卡总览!$J$9*$F$5<=0),0,MIN($D$5,K14-关卡总览!$J$9*$F$5+0)) -> 96 | M14: =IF(OR(L14<=0,L14-0<=0),0,MIN($D$5,L14-0+0)) -> 96 | N14: =IF(OR(M14<=0,M14-0<=0),0,MIN($D$5,M14-0+20)) -> 100 | O14: =IF(OR(N14<=0,N14-0<=0),0,MIN($D$5,N14-0+0)) -> 100 | P14: =IF(OR(O14<=0,O14-0<=0),0,MIN($D$5,O14-0+20)) -> 100 | Q14: =IF(OR(P14<=0,P14-关卡总览!$J$12*$F$5<=0),0,MIN($D$5,P14-关卡总览!$J$12*$F$5+0)) -> 88 | R14: =IF(OR(Q14<=0,Q14-关卡总览!$J$13*$F$5<=0),0,MIN($D$5,Q14-关卡总览!$J$13*$F$5+0)) -> 72 | S14: =IF(OR(R14<=0,R14-0<=0),0,MIN($D$5,R14-0+20)) -> 92 | T14: =IF(OR(S14<=0,S14-关卡总览!$J$14*$F$5<=0),0,MIN($D$5,S14-关卡总览!$J$14*$F$5+0)) -> 70 | V14: =IF(J14>0,MIN(MAX(0,$D$5-(J14-0)),0),0) -> 0 | W14: =IF(K14>关卡总览!$J$9*$F$5,MIN(MAX(0,$D$5-(K14-关卡总览!$J$9*$F$5)),0),0) -> 0 | X14: =IF(L14>0,MIN(MAX(0,$D$5-(L14-0)),0),0) -> 0 | Y14: =IF(M14>0,MIN(MAX(0,$D$5-(M14-0)),20),0) -> 4 | Z14: =IF(N14>0,MIN(MAX(0,$D$5-(N14-0)),0),0) -> 0 | AA14: =IF(O14>0,MIN(MAX(0,$D$5-(O14-0)),20),0) -> 0 | AB14: =IF(P14>关卡总览!$J$12*$F$5,MIN(MAX(0,$D$5-(P14-关卡总览!$J$12*$F$5)),0),0) -> 0 | AC14: =IF(Q14>关卡总览!$J$13*$F$5,MIN(MAX(0,$D$5-(Q14-关卡总览!$J$13*$F$5)),0),0) -> 0 | AD14: =IF(R14>0,MIN(MAX(0,$D$5-(R14-0)),20),0) -> 20 | AE14: =IF(S14>关卡总览!$J$14*$F$5,MIN(MAX(0,$D$5-(S14-关卡总览!$J$14*$F$5)),0),0) -> 0
A15: 7 | B15: 02_02 → 03_03 → 04_02 → 05_02 → 06_01 → 07_01 → 08_01 → 09_01 | C15: 3 | D15: =IF(OR(关卡总览!$K$9<>"已扣完",关卡总览!$K$11<>"已扣完",关卡总览!$K$13<>"已扣完",关卡总览!$K$14<>"已扣完"),"待补脚本",关卡总览!$J$9*$F$5+关卡总览!$J$11*$F$5+关卡总览!$J$13*$F$5+关卡总览!$J$14*$F$5) -> 54 | E15: =IF(OR(关卡总览!$K$9<>"已扣完",关卡总览!$K$11<>"已扣完",关卡总览!$K$13<>"已扣完",关卡总览!$K$14<>"已扣完"),"待补脚本",SUM(V15:AE15)) -> 24 | F15: =IF(OR(关卡总览!$K$9<>"已扣完",关卡总览!$K$11<>"已扣完",关卡总览!$K$13<>"已扣完",关卡总览!$K$14<>"已扣完"),"待补脚本",S15) -> 92 | G15: =IF(OR(关卡总览!$K$9<>"已扣完",关卡总览!$K$11<>"已扣完",关卡总览!$K$13<>"已扣完",关卡总览!$K$14<>"已扣完"),"待补脚本",T15) -> 70 | H15: =IF(OR(关卡总览!$K$9<>"已扣完",关卡总览!$K$11<>"已扣完",关卡总览!$K$13<>"已扣完",关卡总览!$K$14<>"已扣完"),"待补脚本",IF(T15<=0,"预算耗尽","有余量")) -> 有余量 | J15: =$B$5 -> 100 | K15: =IF(OR(J15<=0,J15-0<=0),0,MIN($D$5,J15-0+0)) -> 100 | L15: =IF(OR(K15<=0,K15-关卡总览!$J$9*$F$5<=0),0,MIN($D$5,K15-关卡总览!$J$9*$F$5+0)) -> 96 | M15: =IF(OR(L15<=0,L15-0<=0),0,MIN($D$5,L15-0+0)) -> 96 | N15: =IF(OR(M15<=0,M15-0<=0),0,MIN($D$5,M15-0+20)) -> 100 | O15: =IF(OR(N15<=0,N15-关卡总览!$J$11*$F$5<=0),0,MIN($D$5,N15-关卡总览!$J$11*$F$5+0)) -> 88 | P15: =IF(OR(O15<=0,O15-0<=0),0,MIN($D$5,O15-0+0)) -> 88 | Q15: =IF(OR(P15<=0,P15-0<=0),0,MIN($D$5,P15-0+0)) -> 88 | R15: =IF(OR(Q15<=0,Q15-关卡总览!$J$13*$F$5<=0),0,MIN($D$5,Q15-关卡总览!$J$13*$F$5+0)) -> 72 | S15: =IF(OR(R15<=0,R15-0<=0),0,MIN($D$5,R15-0+20)) -> 92 | T15: =IF(OR(S15<=0,S15-关卡总览!$J$14*$F$5<=0),0,MIN($D$5,S15-关卡总览!$J$14*$F$5+0)) -> 70 | V15: =IF(J15>0,MIN(MAX(0,$D$5-(J15-0)),0),0) -> 0 | W15: =IF(K15>关卡总览!$J$9*$F$5,MIN(MAX(0,$D$5-(K15-关卡总览!$J$9*$F$5)),0),0) -> 0 | X15: =IF(L15>0,MIN(MAX(0,$D$5-(L15-0)),0),0) -> 0 | Y15: =IF(M15>0,MIN(MAX(0,$D$5-(M15-0)),20),0) -> 4 | Z15: =IF(N15>关卡总览!$J$11*$F$5,MIN(MAX(0,$D$5-(N15-关卡总览!$J$11*$F$5)),0),0) -> 0 | AA15: =IF(O15>0,MIN(MAX(0,$D$5-(O15-0)),0),0) -> 0 | AB15: =IF(P15>0,MIN(MAX(0,$D$5-(P15-0)),0),0) -> 0 | AC15: =IF(Q15>关卡总览!$J$13*$F$5,MIN(MAX(0,$D$5-(Q15-关卡总览!$J$13*$F$5)),0),0) -> 0 | AD15: =IF(R15>0,MIN(MAX(0,$D$5-(R15-0)),20),0) -> 20 | AE15: =IF(S15>关卡总览!$J$14*$F$5,MIN(MAX(0,$D$5-(S15-关卡总览!$J$14*$F$5)),0),0) -> 0
A16: 8 | B16: 02_02 → 03_03 → 04_02 → 05_02 → 06_01 → 07_02 → 08_01 → 09_01 | C16: 4 | D16: =IF(OR(关卡总览!$K$9<>"已扣完",关卡总览!$K$11<>"已扣完",关卡总览!$K$12<>"已扣完",关卡总览!$K$13<>"已扣完",关卡总览!$K$14<>"已扣完"),"待补脚本",关卡总览!$J$9*$F$5+关卡总览!$J$11*$F$5+关卡总览!$J$12*$F$5+关卡总览!$J$13*$F$5+关卡总览!$J$14*$F$5) -> 66 | E16: =IF(OR(关卡总览!$K$9<>"已扣完",关卡总览!$K$11<>"已扣完",关卡总览!$K$12<>"已扣完",关卡总览!$K$13<>"已扣完",关卡总览!$K$14<>"已扣完"),"待补脚本",SUM(V16:AE16)) -> 24 | F16: =IF(OR(关卡总览!$K$9<>"已扣完",关卡总览!$K$11<>"已扣完",关卡总览!$K$12<>"已扣完",关卡总览!$K$13<>"已扣完",关卡总览!$K$14<>"已扣完"),"待补脚本",S16) -> 80 | G16: =IF(OR(关卡总览!$K$9<>"已扣完",关卡总览!$K$11<>"已扣完",关卡总览!$K$12<>"已扣完",关卡总览!$K$13<>"已扣完",关卡总览!$K$14<>"已扣完"),"待补脚本",T16) -> 58 | H16: =IF(OR(关卡总览!$K$9<>"已扣完",关卡总览!$K$11<>"已扣完",关卡总览!$K$12<>"已扣完",关卡总览!$K$13<>"已扣完",关卡总览!$K$14<>"已扣完"),"待补脚本",IF(T16<=0,"预算耗尽","有余量")) -> 有余量 | J16: =$B$5 -> 100 | K16: =IF(OR(J16<=0,J16-0<=0),0,MIN($D$5,J16-0+0)) -> 100 | L16: =IF(OR(K16<=0,K16-关卡总览!$J$9*$F$5<=0),0,MIN($D$5,K16-关卡总览!$J$9*$F$5+0)) -> 96 | M16: =IF(OR(L16<=0,L16-0<=0),0,MIN($D$5,L16-0+0)) -> 96 | N16: =IF(OR(M16<=0,M16-0<=0),0,MIN($D$5,M16-0+20)) -> 100 | O16: =IF(OR(N16<=0,N16-关卡总览!$J$11*$F$5<=0),0,MIN($D$5,N16-关卡总览!$J$11*$F$5+0)) -> 88 | P16: =IF(OR(O16<=0,O16-0<=0),0,MIN($D$5,O16-0+0)) -> 88 | Q16: =IF(OR(P16<=0,P16-关卡总览!$J$12*$F$5<=0),0,MIN($D$5,P16-关卡总览!$J$12*$F$5+0)) -> 76 | R16: =IF(OR(Q16<=0,Q16-关卡总览!$J$13*$F$5<=0),0,MIN($D$5,Q16-关卡总览!$J$13*$F$5+0)) -> 60 | S16: =IF(OR(R16<=0,R16-0<=0),0,MIN($D$5,R16-0+20)) -> 80 | T16: =IF(OR(S16<=0,S16-关卡总览!$J$14*$F$5<=0),0,MIN($D$5,S16-关卡总览!$J$14*$F$5+0)) -> 58 | V16: =IF(J16>0,MIN(MAX(0,$D$5-(J16-0)),0),0) -> 0 | W16: =IF(K16>关卡总览!$J$9*$F$5,MIN(MAX(0,$D$5-(K16-关卡总览!$J$9*$F$5)),0),0) -> 0 | X16: =IF(L16>0,MIN(MAX(0,$D$5-(L16-0)),0),0) -> 0 | Y16: =IF(M16>0,MIN(MAX(0,$D$5-(M16-0)),20),0) -> 4 | Z16: =IF(N16>关卡总览!$J$11*$F$5,MIN(MAX(0,$D$5-(N16-关卡总览!$J$11*$F$5)),0),0) -> 0 | AA16: =IF(O16>0,MIN(MAX(0,$D$5-(O16-0)),0),0) -> 0 | AB16: =IF(P16>关卡总览!$J$12*$F$5,MIN(MAX(0,$D$5-(P16-关卡总览!$J$12*$F$5)),0),0) -> 0 | AC16: =IF(Q16>关卡总览!$J$13*$F$5,MIN(MAX(0,$D$5-(Q16-关卡总览!$J$13*$F$5)),0),0) -> 0 | AD16: =IF(R16>0,MIN(MAX(0,$D$5-(R16-0)),20),0) -> 20 | AE16: =IF(S16>关卡总览!$J$14*$F$5,MIN(MAX(0,$D$5-(S16-关卡总览!$J$14*$F$5)),0),0) -> 0
A17: 9 | B17: 02_03 → 03_04 → 04_03 → 05_03 → 06_03 → 07_03 → 08_02 → 09_02 | C17: 3 | D17: =IF(OR(关卡总览!$K$9<>"已扣完",关卡总览!$K$10<>"已扣完",关卡总览!$K$12<>"已扣完",关卡总览!$K$14<>"已扣完"),"待补脚本",关卡总览!$J$9*$F$5+关卡总览!$J$10*$F$5+关卡总览!$J$12*$F$5+关卡总览!$J$14*$F$5) -> 50 | E17: =IF(OR(关卡总览!$K$9<>"已扣完",关卡总览!$K$10<>"已扣完",关卡总览!$K$12<>"已扣完",关卡总览!$K$14<>"已扣完"),"待补脚本",SUM(V17:AE17)) -> 20 | F17: =IF(OR(关卡总览!$K$9<>"已扣完",关卡总览!$K$10<>"已扣完",关卡总览!$K$12<>"已扣完",关卡总览!$K$14<>"已扣完"),"待补脚本",S17) -> 92 | G17: =IF(OR(关卡总览!$K$9<>"已扣完",关卡总览!$K$10<>"已扣完",关卡总览!$K$12<>"已扣完",关卡总览!$K$14<>"已扣完"),"待补脚本",T17) -> 70 | H17: =IF(OR(关卡总览!$K$9<>"已扣完",关卡总览!$K$10<>"已扣完",关卡总览!$K$12<>"已扣完",关卡总览!$K$14<>"已扣完"),"待补脚本",IF(T17<=0,"预算耗尽","有余量")) -> 有余量 | J17: =$B$5 -> 100 | K17: =IF(OR(J17<=0,J17-0<=0),0,MIN($D$5,J17-0+0)) -> 100 | L17: =IF(OR(K17<=0,K17-关卡总览!$J$9*$F$5<=0),0,MIN($D$5,K17-关卡总览!$J$9*$F$5+0)) -> 96 | M17: =IF(OR(L17<=0,L17-0<=0),0,MIN($D$5,L17-0+0)) -> 96 | N17: =IF(OR(M17<=0,M17-关卡总览!$J$10*$F$5<=0),0,MIN($D$5,M17-关卡总览!$J$10*$F$5+0)) -> 84 | O17: =IF(OR(N17<=0,N17-0<=0),0,MIN($D$5,N17-0+0)) -> 84 | P17: =IF(OR(O17<=0,O17-0<=0),0,MIN($D$5,O17-0+0)) -> 84 | Q17: =IF(OR(P17<=0,P17-关卡总览!$J$12*$F$5<=0),0,MIN($D$5,P17-关卡总览!$J$12*$F$5+0)) -> 72 | R17: =IF(OR(Q17<=0,Q17-0<=0),0,MIN($D$5,Q17-0+0)) -> 72 | S17: =IF(OR(R17<=0,R17-0<=0),0,MIN($D$5,R17-0+20)) -> 92 | T17: =IF(OR(S17<=0,S17-关卡总览!$J$14*$F$5<=0),0,MIN($D$5,S17-关卡总览!$J$14*$F$5+0)) -> 70 | V17: =IF(J17>0,MIN(MAX(0,$D$5-(J17-0)),0),0) -> 0 | W17: =IF(K17>关卡总览!$J$9*$F$5,MIN(MAX(0,$D$5-(K17-关卡总览!$J$9*$F$5)),0),0) -> 0 | X17: =IF(L17>0,MIN(MAX(0,$D$5-(L17-0)),0),0) -> 0 | Y17: =IF(M17>关卡总览!$J$10*$F$5,MIN(MAX(0,$D$5-(M17-关卡总览!$J$10*$F$5)),0),0) -> 0 | Z17: =IF(N17>0,MIN(MAX(0,$D$5-(N17-0)),0),0) -> 0 | AA17: =IF(O17>0,MIN(MAX(0,$D$5-(O17-0)),0),0) -> 0 | AB17: =IF(P17>关卡总览!$J$12*$F$5,MIN(MAX(0,$D$5-(P17-关卡总览!$J$12*$F$5)),0),0) -> 0 | AC17: =IF(Q17>0,MIN(MAX(0,$D$5-(Q17-0)),0),0) -> 0 | AD17: =IF(R17>0,MIN(MAX(0,$D$5-(R17-0)),20),0) -> 20 | AE17: =IF(S17>关卡总览!$J$14*$F$5,MIN(MAX(0,$D$5-(S17-关卡总览!$J$14*$F$5)),0),0) -> 0
A18: 10 | B18: 02_03 → 03_04 → 04_03 → 05_03 → 06_03 → 07_03 → 08_03 → 09_02 | C18: 4 | D18: =IF(OR(关卡总览!$K$9<>"已扣完",关卡总览!$K$10<>"已扣完",关卡总览!$K$12<>"已扣完",关卡总览!$K$13<>"已扣完",关卡总览!$K$14<>"已扣完"),"待补脚本",关卡总览!$J$9*$F$5+关卡总览!$J$10*$F$5+关卡总览!$J$12*$F$5+关卡总览!$J$13*$F$5+关卡总览!$J$14*$F$5) -> 66 | E18: =IF(OR(关卡总览!$K$9<>"已扣完",关卡总览!$K$10<>"已扣完",关卡总览!$K$12<>"已扣完",关卡总览!$K$13<>"已扣完",关卡总览!$K$14<>"已扣完"),"待补脚本",SUM(V18:AE18)) -> 20 | F18: =IF(OR(关卡总览!$K$9<>"已扣完",关卡总览!$K$10<>"已扣完",关卡总览!$K$12<>"已扣完",关卡总览!$K$13<>"已扣完",关卡总览!$K$14<>"已扣完"),"待补脚本",S18) -> 76 | G18: =IF(OR(关卡总览!$K$9<>"已扣完",关卡总览!$K$10<>"已扣完",关卡总览!$K$12<>"已扣完",关卡总览!$K$13<>"已扣完",关卡总览!$K$14<>"已扣完"),"待补脚本",T18) -> 54 | H18: =IF(OR(关卡总览!$K$9<>"已扣完",关卡总览!$K$10<>"已扣完",关卡总览!$K$12<>"已扣完",关卡总览!$K$13<>"已扣完",关卡总览!$K$14<>"已扣完"),"待补脚本",IF(T18<=0,"预算耗尽","有余量")) -> 有余量 | J18: =$B$5 -> 100 | K18: =IF(OR(J18<=0,J18-0<=0),0,MIN($D$5,J18-0+0)) -> 100 | L18: =IF(OR(K18<=0,K18-关卡总览!$J$9*$F$5<=0),0,MIN($D$5,K18-关卡总览!$J$9*$F$5+0)) -> 96 | M18: =IF(OR(L18<=0,L18-0<=0),0,MIN($D$5,L18-0+0)) -> 96 | N18: =IF(OR(M18<=0,M18-关卡总览!$J$10*$F$5<=0),0,MIN($D$5,M18-关卡总览!$J$10*$F$5+0)) -> 84 | O18: =IF(OR(N18<=0,N18-0<=0),0,MIN($D$5,N18-0+0)) -> 84 | P18: =IF(OR(O18<=0,O18-0<=0),0,MIN($D$5,O18-0+0)) -> 84 | Q18: =IF(OR(P18<=0,P18-关卡总览!$J$12*$F$5<=0),0,MIN($D$5,P18-关卡总览!$J$12*$F$5+0)) -> 72 | R18: =IF(OR(Q18<=0,Q18-关卡总览!$J$13*$F$5<=0),0,MIN($D$5,Q18-关卡总览!$J$13*$F$5+0)) -> 56 | S18: =IF(OR(R18<=0,R18-0<=0),0,MIN($D$5,R18-0+20)) -> 76 | T18: =IF(OR(S18<=0,S18-关卡总览!$J$14*$F$5<=0),0,MIN($D$5,S18-关卡总览!$J$14*$F$5+0)) -> 54 | V18: =IF(J18>0,MIN(MAX(0,$D$5-(J18-0)),0),0) -> 0 | W18: =IF(K18>关卡总览!$J$9*$F$5,MIN(MAX(0,$D$5-(K18-关卡总览!$J$9*$F$5)),0),0) -> 0 | X18: =IF(L18>0,MIN(MAX(0,$D$5-(L18-0)),0),0) -> 0 | Y18: =IF(M18>关卡总览!$J$10*$F$5,MIN(MAX(0,$D$5-(M18-关卡总览!$J$10*$F$5)),0),0) -> 0 | Z18: =IF(N18>0,MIN(MAX(0,$D$5-(N18-0)),0),0) -> 0 | AA18: =IF(O18>0,MIN(MAX(0,$D$5-(O18-0)),0),0) -> 0 | AB18: =IF(P18>关卡总览!$J$12*$F$5,MIN(MAX(0,$D$5-(P18-关卡总览!$J$12*$F$5)),0),0) -> 0 | AC18: =IF(Q18>关卡总览!$J$13*$F$5,MIN(MAX(0,$D$5-(Q18-关卡总览!$J$13*$F$5)),0),0) -> 0 | AD18: =IF(R18>0,MIN(MAX(0,$D$5-(R18-0)),20),0) -> 20 | AE18: =IF(S18>关卡总览!$J$14*$F$5,MIN(MAX(0,$D$5-(S18-关卡总览!$J$14*$F$5)),0),0) -> 0
A19: 11 | B19: 02_03 → 03_04 → 04_03 → 05_03 → 06_02 → 07_03 → 08_02 → 09_02 | C19: 3 | D19: =IF(OR(关卡总览!$K$9<>"已扣完",关卡总览!$K$10<>"已扣完",关卡总览!$K$12<>"已扣完",关卡总览!$K$14<>"已扣完"),"待补脚本",关卡总览!$J$9*$F$5+关卡总览!$J$10*$F$5+关卡总览!$J$12*$F$5+关卡总览!$J$14*$F$5) -> 50 | E19: =IF(OR(关卡总览!$K$9<>"已扣完",关卡总览!$K$10<>"已扣完",关卡总览!$K$12<>"已扣完",关卡总览!$K$14<>"已扣完"),"待补脚本",SUM(V19:AE19)) -> 28 | F19: =IF(OR(关卡总览!$K$9<>"已扣完",关卡总览!$K$10<>"已扣完",关卡总览!$K$12<>"已扣完",关卡总览!$K$14<>"已扣完"),"待补脚本",S19) -> 100 | G19: =IF(OR(关卡总览!$K$9<>"已扣完",关卡总览!$K$10<>"已扣完",关卡总览!$K$12<>"已扣完",关卡总览!$K$14<>"已扣完"),"待补脚本",T19) -> 78 | H19: =IF(OR(关卡总览!$K$9<>"已扣完",关卡总览!$K$10<>"已扣完",关卡总览!$K$12<>"已扣完",关卡总览!$K$14<>"已扣完"),"待补脚本",IF(T19<=0,"预算耗尽","有余量")) -> 有余量 | J19: =$B$5 -> 100 | K19: =IF(OR(J19<=0,J19-0<=0),0,MIN($D$5,J19-0+0)) -> 100 | L19: =IF(OR(K19<=0,K19-关卡总览!$J$9*$F$5<=0),0,MIN($D$5,K19-关卡总览!$J$9*$F$5+0)) -> 96 | M19: =IF(OR(L19<=0,L19-0<=0),0,MIN($D$5,L19-0+0)) -> 96 | N19: =IF(OR(M19<=0,M19-关卡总览!$J$10*$F$5<=0),0,MIN($D$5,M19-关卡总览!$J$10*$F$5+0)) -> 84 | O19: =IF(OR(N19<=0,N19-0<=0),0,MIN($D$5,N19-0+0)) -> 84 | P19: =IF(OR(O19<=0,O19-0<=0),0,MIN($D$5,O19-0+20)) -> 100 | Q19: =IF(OR(P19<=0,P19-关卡总览!$J$12*$F$5<=0),0,MIN($D$5,P19-关卡总览!$J$12*$F$5+0)) -> 88 | R19: =IF(OR(Q19<=0,Q19-0<=0),0,MIN($D$5,Q19-0+0)) -> 88 | S19: =IF(OR(R19<=0,R19-0<=0),0,MIN($D$5,R19-0+20)) -> 100 | T19: =IF(OR(S19<=0,S19-关卡总览!$J$14*$F$5<=0),0,MIN($D$5,S19-关卡总览!$J$14*$F$5+0)) -> 78 | V19: =IF(J19>0,MIN(MAX(0,$D$5-(J19-0)),0),0) -> 0 | W19: =IF(K19>关卡总览!$J$9*$F$5,MIN(MAX(0,$D$5-(K19-关卡总览!$J$9*$F$5)),0),0) -> 0 | X19: =IF(L19>0,MIN(MAX(0,$D$5-(L19-0)),0),0) -> 0 | Y19: =IF(M19>关卡总览!$J$10*$F$5,MIN(MAX(0,$D$5-(M19-关卡总览!$J$10*$F$5)),0),0) -> 0 | Z19: =IF(N19>0,MIN(MAX(0,$D$5-(N19-0)),0),0) -> 0 | AA19: =IF(O19>0,MIN(MAX(0,$D$5-(O19-0)),20),0) -> 16 | AB19: =IF(P19>关卡总览!$J$12*$F$5,MIN(MAX(0,$D$5-(P19-关卡总览!$J$12*$F$5)),0),0) -> 0 | AC19: =IF(Q19>0,MIN(MAX(0,$D$5-(Q19-0)),0),0) -> 0 | AD19: =IF(R19>0,MIN(MAX(0,$D$5-(R19-0)),20),0) -> 12 | AE19: =IF(S19>关卡总览!$J$14*$F$5,MIN(MAX(0,$D$5-(S19-关卡总览!$J$14*$F$5)),0),0) -> 0
A20: 12 | B20: 02_03 → 03_04 → 04_03 → 05_03 → 06_02 → 07_03 → 08_03 → 09_02 | C20: 4 | D20: =IF(OR(关卡总览!$K$9<>"已扣完",关卡总览!$K$10<>"已扣完",关卡总览!$K$12<>"已扣完",关卡总览!$K$13<>"已扣完",关卡总览!$K$14<>"已扣完"),"待补脚本",关卡总览!$J$9*$F$5+关卡总览!$J$10*$F$5+关卡总览!$J$12*$F$5+关卡总览!$J$13*$F$5+关卡总览!$J$14*$F$5) -> 66 | E20: =IF(OR(关卡总览!$K$9<>"已扣完",关卡总览!$K$10<>"已扣完",关卡总览!$K$12<>"已扣完",关卡总览!$K$13<>"已扣完",关卡总览!$K$14<>"已扣完"),"待补脚本",SUM(V20:AE20)) -> 36 | F20: =IF(OR(关卡总览!$K$9<>"已扣完",关卡总览!$K$10<>"已扣完",关卡总览!$K$12<>"已扣完",关卡总览!$K$13<>"已扣完",关卡总览!$K$14<>"已扣完"),"待补脚本",S20) -> 92 | G20: =IF(OR(关卡总览!$K$9<>"已扣完",关卡总览!$K$10<>"已扣完",关卡总览!$K$12<>"已扣完",关卡总览!$K$13<>"已扣完",关卡总览!$K$14<>"已扣完"),"待补脚本",T20) -> 70 | H20: =IF(OR(关卡总览!$K$9<>"已扣完",关卡总览!$K$10<>"已扣完",关卡总览!$K$12<>"已扣完",关卡总览!$K$13<>"已扣完",关卡总览!$K$14<>"已扣完"),"待补脚本",IF(T20<=0,"预算耗尽","有余量")) -> 有余量 | J20: =$B$5 -> 100 | K20: =IF(OR(J20<=0,J20-0<=0),0,MIN($D$5,J20-0+0)) -> 100 | L20: =IF(OR(K20<=0,K20-关卡总览!$J$9*$F$5<=0),0,MIN($D$5,K20-关卡总览!$J$9*$F$5+0)) -> 96 | M20: =IF(OR(L20<=0,L20-0<=0),0,MIN($D$5,L20-0+0)) -> 96 | N20: =IF(OR(M20<=0,M20-关卡总览!$J$10*$F$5<=0),0,MIN($D$5,M20-关卡总览!$J$10*$F$5+0)) -> 84 | O20: =IF(OR(N20<=0,N20-0<=0),0,MIN($D$5,N20-0+0)) -> 84 | P20: =IF(OR(O20<=0,O20-0<=0),0,MIN($D$5,O20-0+20)) -> 100 | Q20: =IF(OR(P20<=0,P20-关卡总览!$J$12*$F$5<=0),0,MIN($D$5,P20-关卡总览!$J$12*$F$5+0)) -> 88 | R20: =IF(OR(Q20<=0,Q20-关卡总览!$J$13*$F$5<=0),0,MIN($D$5,Q20-关卡总览!$J$13*$F$5+0)) -> 72 | S20: =IF(OR(R20<=0,R20-0<=0),0,MIN($D$5,R20-0+20)) -> 92 | T20: =IF(OR(S20<=0,S20-关卡总览!$J$14*$F$5<=0),0,MIN($D$5,S20-关卡总览!$J$14*$F$5+0)) -> 70 | V20: =IF(J20>0,MIN(MAX(0,$D$5-(J20-0)),0),0) -> 0 | W20: =IF(K20>关卡总览!$J$9*$F$5,MIN(MAX(0,$D$5-(K20-关卡总览!$J$9*$F$5)),0),0) -> 0 | X20: =IF(L20>0,MIN(MAX(0,$D$5-(L20-0)),0),0) -> 0 | Y20: =IF(M20>关卡总览!$J$10*$F$5,MIN(MAX(0,$D$5-(M20-关卡总览!$J$10*$F$5)),0),0) -> 0 | Z20: =IF(N20>0,MIN(MAX(0,$D$5-(N20-0)),0),0) -> 0 | AA20: =IF(O20>0,MIN(MAX(0,$D$5-(O20-0)),20),0) -> 16 | AB20: =IF(P20>关卡总览!$J$12*$F$5,MIN(MAX(0,$D$5-(P20-关卡总览!$J$12*$F$5)),0),0) -> 0 | AC20: =IF(Q20>关卡总览!$J$13*$F$5,MIN(MAX(0,$D$5-(Q20-关卡总览!$J$13*$F$5)),0),0) -> 0 | AD20: =IF(R20>0,MIN(MAX(0,$D$5-(R20-0)),20),0) -> 20 | AE20: =IF(S20>关卡总览!$J$14*$F$5,MIN(MAX(0,$D$5-(S20-关卡总览!$J$14*$F$5)),0),0) -> 0
A21: 13 | B21: 02_01 → 03_01 → 04_01 → 05_01 → 06_01 → 07_01 → 08_01 → 09_01 | C21: 2 | D21: =IF(OR(关卡总览!$K$9<>"已扣完",关卡总览!$K$13<>"已扣完",关卡总览!$K$14<>"已扣完"),"待补脚本",关卡总览!$J$9*$F$5+关卡总览!$J$13*$F$5+关卡总览!$J$14*$F$5) -> 42 | E21: =IF(OR(关卡总览!$K$9<>"已扣完",关卡总览!$K$13<>"已扣完",关卡总览!$K$14<>"已扣完"),"待补脚本",SUM(V21:AE21)) -> 20 | F21: =IF(OR(关卡总览!$K$9<>"已扣完",关卡总览!$K$13<>"已扣完",关卡总览!$K$14<>"已扣完"),"待补脚本",S21) -> 100 | G21: =IF(OR(关卡总览!$K$9<>"已扣完",关卡总览!$K$13<>"已扣完",关卡总览!$K$14<>"已扣完"),"待补脚本",T21) -> 78 | H21: =IF(OR(关卡总览!$K$9<>"已扣完",关卡总览!$K$13<>"已扣完",关卡总览!$K$14<>"已扣完"),"待补脚本",IF(T21<=0,"预算耗尽","有余量")) -> 有余量 | J21: =$B$5 -> 100 | K21: =IF(OR(J21<=0,J21-0<=0),0,MIN($D$5,J21-0+0)) -> 100 | L21: =IF(OR(K21<=0,K21-关卡总览!$J$9*$F$5<=0),0,MIN($D$5,K21-关卡总览!$J$9*$F$5+0)) -> 96 | M21: =IF(OR(L21<=0,L21-0<=0),0,MIN($D$5,L21-0+0)) -> 96 | N21: =IF(OR(M21<=0,M21-0<=0),0,MIN($D$5,M21-0+0)) -> 96 | O21: =IF(OR(N21<=0,N21-0<=0),0,MIN($D$5,N21-0+0)) -> 96 | P21: =IF(OR(O21<=0,O21-0<=0),0,MIN($D$5,O21-0+0)) -> 96 | Q21: =IF(OR(P21<=0,P21-0<=0),0,MIN($D$5,P21-0+0)) -> 96 | R21: =IF(OR(Q21<=0,Q21-关卡总览!$J$13*$F$5<=0),0,MIN($D$5,Q21-关卡总览!$J$13*$F$5+0)) -> 80 | S21: =IF(OR(R21<=0,R21-0<=0),0,MIN($D$5,R21-0+20)) -> 100 | T21: =IF(OR(S21<=0,S21-关卡总览!$J$14*$F$5<=0),0,MIN($D$5,S21-关卡总览!$J$14*$F$5+0)) -> 78 | V21: =IF(J21>0,MIN(MAX(0,$D$5-(J21-0)),0),0) -> 0 | W21: =IF(K21>关卡总览!$J$9*$F$5,MIN(MAX(0,$D$5-(K21-关卡总览!$J$9*$F$5)),0),0) -> 0 | X21: =IF(L21>0,MIN(MAX(0,$D$5-(L21-0)),0),0) -> 0 | Y21: =IF(M21>0,MIN(MAX(0,$D$5-(M21-0)),0),0) -> 0 | Z21: =IF(N21>0,MIN(MAX(0,$D$5-(N21-0)),0),0) -> 0 | AA21: =IF(O21>0,MIN(MAX(0,$D$5-(O21-0)),0),0) -> 0 | AB21: =IF(P21>0,MIN(MAX(0,$D$5-(P21-0)),0),0) -> 0 | AC21: =IF(Q21>关卡总览!$J$13*$F$5,MIN(MAX(0,$D$5-(Q21-关卡总览!$J$13*$F$5)),0),0) -> 0 | AD21: =IF(R21>0,MIN(MAX(0,$D$5-(R21-0)),20),0) -> 20 | AE21: =IF(S21>关卡总览!$J$14*$F$5,MIN(MAX(0,$D$5-(S21-关卡总览!$J$14*$F$5)),0),0) -> 0
A22: 14 | B22: 02_01 → 03_01 → 04_01 → 05_01 → 06_01 → 07_02 → 08_01 → 09_01 | C22: 3 | D22: =IF(OR(关卡总览!$K$9<>"已扣完",关卡总览!$K$12<>"已扣完",关卡总览!$K$13<>"已扣完",关卡总览!$K$14<>"已扣完"),"待补脚本",关卡总览!$J$9*$F$5+关卡总览!$J$12*$F$5+关卡总览!$J$13*$F$5+关卡总览!$J$14*$F$5) -> 54 | E22: =IF(OR(关卡总览!$K$9<>"已扣完",关卡总览!$K$12<>"已扣完",关卡总览!$K$13<>"已扣完",关卡总览!$K$14<>"已扣完"),"待补脚本",SUM(V22:AE22)) -> 20 | F22: =IF(OR(关卡总览!$K$9<>"已扣完",关卡总览!$K$12<>"已扣完",关卡总览!$K$13<>"已扣完",关卡总览!$K$14<>"已扣完"),"待补脚本",S22) -> 88 | G22: =IF(OR(关卡总览!$K$9<>"已扣完",关卡总览!$K$12<>"已扣完",关卡总览!$K$13<>"已扣完",关卡总览!$K$14<>"已扣完"),"待补脚本",T22) -> 66 | H22: =IF(OR(关卡总览!$K$9<>"已扣完",关卡总览!$K$12<>"已扣完",关卡总览!$K$13<>"已扣完",关卡总览!$K$14<>"已扣完"),"待补脚本",IF(T22<=0,"预算耗尽","有余量")) -> 有余量 | J22: =$B$5 -> 100 | K22: =IF(OR(J22<=0,J22-0<=0),0,MIN($D$5,J22-0+0)) -> 100 | L22: =IF(OR(K22<=0,K22-关卡总览!$J$9*$F$5<=0),0,MIN($D$5,K22-关卡总览!$J$9*$F$5+0)) -> 96 | M22: =IF(OR(L22<=0,L22-0<=0),0,MIN($D$5,L22-0+0)) -> 96 | N22: =IF(OR(M22<=0,M22-0<=0),0,MIN($D$5,M22-0+0)) -> 96 | O22: =IF(OR(N22<=0,N22-0<=0),0,MIN($D$5,N22-0+0)) -> 96 | P22: =IF(OR(O22<=0,O22-0<=0),0,MIN($D$5,O22-0+0)) -> 96 | Q22: =IF(OR(P22<=0,P22-关卡总览!$J$12*$F$5<=0),0,MIN($D$5,P22-关卡总览!$J$12*$F$5+0)) -> 84 | R22: =IF(OR(Q22<=0,Q22-关卡总览!$J$13*$F$5<=0),0,MIN($D$5,Q22-关卡总览!$J$13*$F$5+0)) -> 68 | S22: =IF(OR(R22<=0,R22-0<=0),0,MIN($D$5,R22-0+20)) -> 88 | T22: =IF(OR(S22<=0,S22-关卡总览!$J$14*$F$5<=0),0,MIN($D$5,S22-关卡总览!$J$14*$F$5+0)) -> 66 | V22: =IF(J22>0,MIN(MAX(0,$D$5-(J22-0)),0),0) -> 0 | W22: =IF(K22>关卡总览!$J$9*$F$5,MIN(MAX(0,$D$5-(K22-关卡总览!$J$9*$F$5)),0),0) -> 0 | X22: =IF(L22>0,MIN(MAX(0,$D$5-(L22-0)),0),0) -> 0 | Y22: =IF(M22>0,MIN(MAX(0,$D$5-(M22-0)),0),0) -> 0 | Z22: =IF(N22>0,MIN(MAX(0,$D$5-(N22-0)),0),0) -> 0 | AA22: =IF(O22>0,MIN(MAX(0,$D$5-(O22-0)),0),0) -> 0 | AB22: =IF(P22>关卡总览!$J$12*$F$5,MIN(MAX(0,$D$5-(P22-关卡总览!$J$12*$F$5)),0),0) -> 0 | AC22: =IF(Q22>关卡总览!$J$13*$F$5,MIN(MAX(0,$D$5-(Q22-关卡总览!$J$13*$F$5)),0),0) -> 0 | AD22: =IF(R22>0,MIN(MAX(0,$D$5-(R22-0)),20),0) -> 20 | AE22: =IF(S22>关卡总览!$J$14*$F$5,MIN(MAX(0,$D$5-(S22-关卡总览!$J$14*$F$5)),0),0) -> 0
A25: 路线上共2–4场普通战斗、1场Boss、1–3次20点休息；全部共14条路径。入场生命模型没有加入药水收益、购物支出或尚未获得的新征召牌。 | B25: 路线上共2–4场普通战斗、1场Boss、1–3次20点休息；全部共14条路径。入场生命模型没有加入药水收益、购物支出或尚未获得的新征召牌。 | C25: 路线上共2–4场普通战斗、1场Boss、1–3次20点休息；全部共14条路径。入场生命模型没有加入药水收益、购物支出或尚未获得的新征召牌。 | D25: 路线上共2–4场普通战斗、1场Boss、1–3次20点休息；全部共14条路径。入场生命模型没有加入药水收益、购物支出或尚未获得的新征召牌。 | E25: 路线上共2–4场普通战斗、1场Boss、1–3次20点休息；全部共14条路径。入场生命模型没有加入药水收益、购物支出或尚未获得的新征召牌。 | F25: 路线上共2–4场普通战斗、1场Boss、1–3次20点休息；全部共14条路径。入场生命模型没有加入药水收益、购物支出或尚未获得的新征召牌。 | G25: 路线上共2–4场普通战斗、1场Boss、1–3次20点休息；全部共14条路径。入场生命模型没有加入药水收益、购物支出或尚未获得的新征召牌。 | H25: 路线上共2–4场普通战斗、1场Boss、1–3次20点休息；全部共14条路径。入场生命模型没有加入药水收益、购物支出或尚未获得的新征召牌。
A26: 路线上共2–4场普通战斗、1场Boss、1–3次20点休息；全部共14条路径。入场生命模型没有加入药水收益、购物支出或尚未获得的新征召牌。 | B26: 路线上共2–4场普通战斗、1场Boss、1–3次20点休息；全部共14条路径。入场生命模型没有加入药水收益、购物支出或尚未获得的新征召牌。 | C26: 路线上共2–4场普通战斗、1场Boss、1–3次20点休息；全部共14条路径。入场生命模型没有加入药水收益、购物支出或尚未获得的新征召牌。 | D26: 路线上共2–4场普通战斗、1场Boss、1–3次20点休息；全部共14条路径。入场生命模型没有加入药水收益、购物支出或尚未获得的新征召牌。 | E26: 路线上共2–4场普通战斗、1场Boss、1–3次20点休息；全部共14条路径。入场生命模型没有加入药水收益、购物支出或尚未获得的新征召牌。 | F26: 路线上共2–4场普通战斗、1场Boss、1–3次20点休息；全部共14条路径。入场生命模型没有加入药水收益、购物支出或尚未获得的新征召牌。 | G26: 路线上共2–4场普通战斗、1场Boss、1–3次20点休息；全部共14条路径。入场生命模型没有加入药水收益、购物支出或尚未获得的新征召牌。 | H26: 路线上共2–4场普通战斗、1场Boss、1–3次20点休息；全部共14条路径。入场生命模型没有加入药水收益、购物支出或尚未获得的新征召牌。
A28: 源：data/levels/第一章 · 翠绿原野.json。当前有5个节点标题与type不一致；本表保留type，不将事件误算为战斗。数值预算依赖波次表的假设结算，不代表实测平均值。 | B28: 源：data/levels/第一章 · 翠绿原野.json。当前有5个节点标题与type不一致；本表保留type，不将事件误算为战斗。数值预算依赖波次表的假设结算，不代表实测平均值。 | C28: 源：data/levels/第一章 · 翠绿原野.json。当前有5个节点标题与type不一致；本表保留type，不将事件误算为战斗。数值预算依赖波次表的假设结算，不代表实测平均值。 | D28: 源：data/levels/第一章 · 翠绿原野.json。当前有5个节点标题与type不一致；本表保留type，不将事件误算为战斗。数值预算依赖波次表的假设结算，不代表实测平均值。 | E28: 源：data/levels/第一章 · 翠绿原野.json。当前有5个节点标题与type不一致；本表保留type，不将事件误算为战斗。数值预算依赖波次表的假设结算，不代表实测平均值。 | F28: 源：data/levels/第一章 · 翠绿原野.json。当前有5个节点标题与type不一致；本表保留type，不将事件误算为战斗。数值预算依赖波次表的假设结算，不代表实测平均值。 | G28: 源：data/levels/第一章 · 翠绿原野.json。当前有5个节点标题与type不一致；本表保留type，不将事件误算为战斗。数值预算依赖波次表的假设结算，不代表实测平均值。 | H28: 源：data/levels/第一章 · 翠绿原野.json。当前有5个节点标题与type不一致；本表保留type，不将事件误算为战斗。数值预算依赖波次表的假设结算，不代表实测平均值。
A29: 源：data/levels/第一章 · 翠绿原野.json。当前有5个节点标题与type不一致；本表保留type，不将事件误算为战斗。数值预算依赖波次表的假设结算，不代表实测平均值。 | B29: 源：data/levels/第一章 · 翠绿原野.json。当前有5个节点标题与type不一致；本表保留type，不将事件误算为战斗。数值预算依赖波次表的假设结算，不代表实测平均值。 | C29: 源：data/levels/第一章 · 翠绿原野.json。当前有5个节点标题与type不一致；本表保留type，不将事件误算为战斗。数值预算依赖波次表的假设结算，不代表实测平均值。 | D29: 源：data/levels/第一章 · 翠绿原野.json。当前有5个节点标题与type不一致；本表保留type，不将事件误算为战斗。数值预算依赖波次表的假设结算，不代表实测平均值。 | E29: 源：data/levels/第一章 · 翠绿原野.json。当前有5个节点标题与type不一致；本表保留type，不将事件误算为战斗。数值预算依赖波次表的假设结算，不代表实测平均值。 | F29: 源：data/levels/第一章 · 翠绿原野.json。当前有5个节点标题与type不一致；本表保留type，不将事件误算为战斗。数值预算依赖波次表的假设结算，不代表实测平均值。 | G29: 源：data/levels/第一章 · 翠绿原野.json。当前有5个节点标题与type不一致；本表保留type，不将事件误算为战斗。数值预算依赖波次表的假设结算，不代表实测平均值。 | H29: 源：data/levels/第一章 · 翠绿原野.json。当前有5个节点标题与type不一致；本表保留type，不将事件误算为战斗。数值预算依赖波次表的假设结算，不代表实测平均值。
A30: 源：data/levels/第一章 · 翠绿原野.json。当前有5个节点标题与type不一致；本表保留type，不将事件误算为战斗。数值预算依赖波次表的假设结算，不代表实测平均值。 | B30: 源：data/levels/第一章 · 翠绿原野.json。当前有5个节点标题与type不一致；本表保留type，不将事件误算为战斗。数值预算依赖波次表的假设结算，不代表实测平均值。 | C30: 源：data/levels/第一章 · 翠绿原野.json。当前有5个节点标题与type不一致；本表保留type，不将事件误算为战斗。数值预算依赖波次表的假设结算，不代表实测平均值。 | D30: 源：data/levels/第一章 · 翠绿原野.json。当前有5个节点标题与type不一致；本表保留type，不将事件误算为战斗。数值预算依赖波次表的假设结算，不代表实测平均值。 | E30: 源：data/levels/第一章 · 翠绿原野.json。当前有5个节点标题与type不一致；本表保留type，不将事件误算为战斗。数值预算依赖波次表的假设结算，不代表实测平均值。 | F30: 源：data/levels/第一章 · 翠绿原野.json。当前有5个节点标题与type不一致；本表保留type，不将事件误算为战斗。数值预算依赖波次表的假设结算，不代表实测平均值。 | G30: 源：data/levels/第一章 · 翠绿原野.json。当前有5个节点标题与type不一致；本表保留type，不将事件误算为战斗。数值预算依赖波次表的假设结算，不代表实测平均值。 | H30: 源：data/levels/第一章 · 翠绿原野.json。当前有5个节点标题与type不一致；本表保留type，不将事件误算为战斗。数值预算依赖波次表的假设结算，不代表实测平均值。

Sheet 波次与结算
A2: 波次编成与参考结算 | B2: 波次编成与参考结算 | C2: 波次编成与参考结算 | D2: 波次编成与参考结算 | E2: 波次编成与参考结算 | F2: 波次编成与参考结算 | G2: 波次编成与参考结算 | H2: 波次编成与参考结算 | I2: 波次编成与参考结算 | J2: 波次编成与参考结算 | K2: 波次编成与参考结算 | L2: 波次编成与参考结算 | M2: 波次编成与参考结算 | N2: 波次编成与参考结算 | O2: 波次编成与参考结算 | P2: 波次编成与参考结算 | Q2: 波次编成与参考结算 | R2: 波次编成与参考结算 | S2: 波次编成与参考结算
A4: 胜负为设计假设：1=我方胜、0=我方败、2=全灭平局；空白=未设参考。兵种属性改变不会自动预测胜负。 | B4: 胜负为设计假设：1=我方胜、0=我方败、2=全灭平局；空白=未设参考。兵种属性改变不会自动预测胜负。 | C4: 胜负为设计假设：1=我方胜、0=我方败、2=全灭平局；空白=未设参考。兵种属性改变不会自动预测胜负。 | D4: 胜负为设计假设：1=我方胜、0=我方败、2=全灭平局；空白=未设参考。兵种属性改变不会自动预测胜负。 | E4: 胜负为设计假设：1=我方胜、0=我方败、2=全灭平局；空白=未设参考。兵种属性改变不会自动预测胜负。 | F4: 胜负为设计假设：1=我方胜、0=我方败、2=全灭平局；空白=未设参考。兵种属性改变不会自动预测胜负。 | G4: 胜负为设计假设：1=我方胜、0=我方败、2=全灭平局；空白=未设参考。兵种属性改变不会自动预测胜负。 | H4: 胜负为设计假设：1=我方胜、0=我方败、2=全灭平局；空白=未设参考。兵种属性改变不会自动预测胜负。 | I4: 胜负为设计假设：1=我方胜、0=我方败、2=全灭平局；空白=未设参考。兵种属性改变不会自动预测胜负。 | J4: 胜负为设计假设：1=我方胜、0=我方败、2=全灭平局；空白=未设参考。兵种属性改变不会自动预测胜负。 | K4: 胜负为设计假设：1=我方胜、0=我方败、2=全灭平局；空白=未设参考。兵种属性改变不会自动预测胜负。 | L4: 胜负为设计假设：1=我方胜、0=我方败、2=全灭平局；空白=未设参考。兵种属性改变不会自动预测胜负。 | M4: 胜负为设计假设：1=我方胜、0=我方败、2=全灭平局；空白=未设参考。兵种属性改变不会自动预测胜负。 | N4: 胜负为设计假设：1=我方胜、0=我方败、2=全灭平局；空白=未设参考。兵种属性改变不会自动预测胜负。 | O4: 胜负为设计假设：1=我方胜、0=我方败、2=全灭平局；空白=未设参考。兵种属性改变不会自动预测胜负。 | P4: 胜负为设计假设：1=我方胜、0=我方败、2=全灭平局；空白=未设参考。兵种属性改变不会自动预测胜负。 | Q4: 胜负为设计假设：1=我方胜、0=我方败、2=全灭平局；空白=未设参考。兵种属性改变不会自动预测胜负。 | R4: 胜负为设计假设：1=我方胜、0=我方败、2=全灭平局；空白=未设参考。兵种属性改变不会自动预测胜负。 | S4: 胜负为设计假设：1=我方胜、0=我方败、2=全灭平局；空白=未设参考。兵种属性改变不会自动预测胜负。
A6: 空波仍占一个回合。非循环耗尽后复用末个非空波；F循环6–10波，无成长。重复编成用公式链接原始波次。 | B6: 空波仍占一个回合。非循环耗尽后复用末个非空波；F循环6–10波，无成长。重复编成用公式链接原始波次。 | C6: 空波仍占一个回合。非循环耗尽后复用末个非空波；F循环6–10波，无成长。重复编成用公式链接原始波次。 | D6: 空波仍占一个回合。非循环耗尽后复用末个非空波；F循环6–10波，无成长。重复编成用公式链接原始波次。 | E6: 空波仍占一个回合。非循环耗尽后复用末个非空波；F循环6–10波，无成长。重复编成用公式链接原始波次。 | F6: 空波仍占一个回合。非循环耗尽后复用末个非空波；F循环6–10波，无成长。重复编成用公式链接原始波次。 | G6: 空波仍占一个回合。非循环耗尽后复用末个非空波；F循环6–10波，无成长。重复编成用公式链接原始波次。 | H6: 空波仍占一个回合。非循环耗尽后复用末个非空波；F循环6–10波，无成长。重复编成用公式链接原始波次。 | I6: 空波仍占一个回合。非循环耗尽后复用末个非空波；F循环6–10波，无成长。重复编成用公式链接原始波次。 | J6: 空波仍占一个回合。非循环耗尽后复用末个非空波；F循环6–10波，无成长。重复编成用公式链接原始波次。 | K6: 空波仍占一个回合。非循环耗尽后复用末个非空波；F循环6–10波，无成长。重复编成用公式链接原始波次。 | L6: 空波仍占一个回合。非循环耗尽后复用末个非空波；F循环6–10波，无成长。重复编成用公式链接原始波次。 | M6: 空波仍占一个回合。非循环耗尽后复用末个非空波；F循环6–10波，无成长。重复编成用公式链接原始波次。 | N6: 空波仍占一个回合。非循环耗尽后复用末个非空波；F循环6–10波，无成长。重复编成用公式链接原始波次。 | O6: 空波仍占一个回合。非循环耗尽后复用末个非空波；F循环6–10波，无成长。重复编成用公式链接原始波次。 | P6: 空波仍占一个回合。非循环耗尽后复用末个非空波；F循环6–10波，无成长。重复编成用公式链接原始波次。 | Q6: 空波仍占一个回合。非循环耗尽后复用末个非空波；F循环6–10波，无成长。重复编成用公式链接原始波次。 | R6: 空波仍占一个回合。非循环耗尽后复用末个非空波；F循环6–10波，无成长。重复编成用公式链接原始波次。 | S6: 空波仍占一个回合。非循环耗尽后复用末个非空波；F循环6–10波，无成长。重复编成用公式链接原始波次。
A8: 配置 | B8: 回合 | C8: S | D8: R | E8: O | F8: T | G8: B | H8: 敌单位生命和 | I8: 敌人数 | J8: 幸存扣血池 | K8: 胜负假设 | L8: 我幸存扣血 | M8: 敌幸存扣血 | N8: 打敌据点 | O8: 玩家战损 | P8: 敌余生命 | Q8: 累计战损 | R8: 基础能量 | S8: 状态 / 说明
A9: A | B9: 1 | C9: 1 | D9: 0 | E9: 0 | F9: 0 | G9: 0 | H9: =C9*敌兵与开局!$C$9+D9*敌兵与开局!$C$10+E9*敌兵与开局!$C$11+F9*敌兵与开局!$C$12+G9*敌兵与开局!$C$13 -> 70 | I9: =SUM(C9:G9) -> 1 | J9: =C9*敌兵与开局!$F$9+D9*敌兵与开局!$F$10+E9*敌兵与开局!$F$11+F9*敌兵与开局!$F$12+G9*敌兵与开局!$F$13 -> 1 | K9: 1 | L9: 2 | M9: 0 | N9: =IF(OR(关卡总览!$D$9<=0,NOT(ISNUMBER(K9))),0,IF(K9=1,B9+L9,0)) -> 3 | O9: =IF(OR(关卡总览!$D$9<=0,NOT(ISNUMBER(K9))),0,IF(K9=0,B9+M9,0)) -> 0 | P9: =MAX(0,关卡总览!$D$9-N9) -> 19 | Q9: =0+O9 -> 0 | R9: =MIN(关卡总览!$E$9+(B9-1)*关卡总览!$F$9,关卡总览!$G$9) -> 3 | S9: =IF(关卡总览!$D$9<=0,"已结束",IF(NOT(ISNUMBER(K9)),"待填写胜负",IF(M9>J9,"敌幸存值超上限",IF(AND(I9=0,K9=0),"空波不可判败","原始波1")))) -> 原始波1
A10: A | B10: 2 | C10: 2 | D10: 0 | E10: 0 | F10: 0 | G10: 0 | H10: =C10*敌兵与开局!$C$9+D10*敌兵与开局!$C$10+E10*敌兵与开局!$C$11+F10*敌兵与开局!$C$12+G10*敌兵与开局!$C$13 -> 140 | I10: =SUM(C10:G10) -> 2 | J10: =C10*敌兵与开局!$F$9+D10*敌兵与开局!$F$10+E10*敌兵与开局!$F$11+F10*敌兵与开局!$F$12+G10*敌兵与开局!$F$13 -> 2 | K10: 1 | L10: 3 | M10: 0 | N10: =IF(OR(P9<=0,NOT(ISNUMBER(K10))),0,IF(K10=1,B10+L10,0)) -> 5 | O10: =IF(OR(P9<=0,NOT(ISNUMBER(K10))),0,IF(K10=0,B10+M10,0)) -> 0 | P10: =MAX(0,P9-N10) -> 14 | Q10: =Q9+O10 -> 0 | R10: =MIN(关卡总览!$E$9+(B10-1)*关卡总览!$F$9,关卡总览!$G$9) -> 4 | S10: =IF(P9<=0,"已结束",IF(NOT(ISNUMBER(K10)),"待填写胜负",IF(M10>J10,"敌幸存值超上限",IF(AND(I10=0,K10=0),"空波不可判败","原始波2")))) -> 原始波2
A11: A | B11: 3 | C11: 1 | D11: 1 | E11: 0 | F11: 0 | G11: 0 | H11: =C11*敌兵与开局!$C$9+D11*敌兵与开局!$C$10+E11*敌兵与开局!$C$11+F11*敌兵与开局!$C$12+G11*敌兵与开局!$C$13 -> 125 | I11: =SUM(C11:G11) -> 2 | J11: =C11*敌兵与开局!$F$9+D11*敌兵与开局!$F$10+E11*敌兵与开局!$F$11+F11*敌兵与开局!$F$12+G11*敌兵与开局!$F$13 -> 3 | K11: 0 | L11: 0 | M11: 1 | N11: =IF(OR(P10<=0,NOT(ISNUMBER(K11))),0,IF(K11=1,B11+L11,0)) -> 0 | O11: =IF(OR(P10<=0,NOT(ISNUMBER(K11))),0,IF(K11=0,B11+M11,0)) -> 4 | P11: =MAX(0,P10-N11) -> 14 | Q11: =Q10+O11 -> 4 | R11: =MIN(关卡总览!$E$9+(B11-1)*关卡总览!$F$9,关卡总览!$G$9) -> 5 | S11: =IF(P10<=0,"已结束",IF(NOT(ISNUMBER(K11)),"待填写胜负",IF(M11>J11,"敌幸存值超上限",IF(AND(I11=0,K11=0),"空波不可判败","原始波3")))) -> 原始波3
A12: A | B12: 4 | C12: 0 | D12: 0 | E12: 0 | F12: 0 | G12: 0 | H12: =C12*敌兵与开局!$C$9+D12*敌兵与开局!$C$10+E12*敌兵与开局!$C$11+F12*敌兵与开局!$C$12+G12*敌兵与开局!$C$13 -> 0 | I12: =SUM(C12:G12) -> 0 | J12: =C12*敌兵与开局!$F$9+D12*敌兵与开局!$F$10+E12*敌兵与开局!$F$11+F12*敌兵与开局!$F$12+G12*敌兵与开局!$F$13 -> 0 | K12: 1 | L12: 3 | M12: 0 | N12: =IF(OR(P11<=0,NOT(ISNUMBER(K12))),0,IF(K12=1,B12+L12,0)) -> 7 | O12: =IF(OR(P11<=0,NOT(ISNUMBER(K12))),0,IF(K12=0,B12+M12,0)) -> 0 | P12: =MAX(0,P11-N12) -> 7 | Q12: =Q11+O12 -> 4 | R12: =MIN(关卡总览!$E$9+(B12-1)*关卡总览!$F$9,关卡总览!$G$9) -> 6 | S12: =IF(P11<=0,"已结束",IF(NOT(ISNUMBER(K12)),"待填写胜负",IF(M12>J12,"敌幸存值超上限",IF(AND(I12=0,K12=0),"空波不可判败","空波")))) -> 空波
A13: A | B13: 5 | C13: 2 | D13: 0 | E13: 0 | F13: 0 | G13: 0 | H13: =C13*敌兵与开局!$C$9+D13*敌兵与开局!$C$10+E13*敌兵与开局!$C$11+F13*敌兵与开局!$C$12+G13*敌兵与开局!$C$13 -> 140 | I13: =SUM(C13:G13) -> 2 | J13: =C13*敌兵与开局!$F$9+D13*敌兵与开局!$F$10+E13*敌兵与开局!$F$11+F13*敌兵与开局!$F$12+G13*敌兵与开局!$F$13 -> 2 | K13: 1 | L13: 2 | M13: 0 | N13: =IF(OR(P12<=0,NOT(ISNUMBER(K13))),0,IF(K13=1,B13+L13,0)) -> 7 | O13: =IF(OR(P12<=0,NOT(ISNUMBER(K13))),0,IF(K13=0,B13+M13,0)) -> 0 | P13: =MAX(0,P12-N13) -> 0 | Q13: =Q12+O13 -> 4 | R13: =MIN(关卡总览!$E$9+(B13-1)*关卡总览!$F$9,关卡总览!$G$9) -> 7 | S13: =IF(P12<=0,"已结束",IF(NOT(ISNUMBER(K13)),"待填写胜负",IF(M13>J13,"敌幸存值超上限",IF(AND(I13=0,K13=0),"空波不可判败","原始波5")))) -> 原始波5
A14: A | B14: 6 | C14: 1 | D14: 0 | E14: 0 | F14: 0 | G14: 0 | H14: =C14*敌兵与开局!$C$9+D14*敌兵与开局!$C$10+E14*敌兵与开局!$C$11+F14*敌兵与开局!$C$12+G14*敌兵与开局!$C$13 -> 70 | I14: =SUM(C14:G14) -> 1 | J14: =C14*敌兵与开局!$F$9+D14*敌兵与开局!$F$10+E14*敌兵与开局!$F$11+F14*敌兵与开局!$F$12+G14*敌兵与开局!$F$13 -> 1 | L14: 0 | M14: 0 | N14: =IF(OR(P13<=0,NOT(ISNUMBER(K14))),0,IF(K14=1,B14+L14,0)) -> 0 | O14: =IF(OR(P13<=0,NOT(ISNUMBER(K14))),0,IF(K14=0,B14+M14,0)) -> 0 | P14: =MAX(0,P13-N14) -> 0 | Q14: =Q13+O14 -> 4 | R14: =MIN(关卡总览!$E$9+(B14-1)*关卡总览!$F$9,关卡总览!$G$9) -> 8 | S14: =IF(P13<=0,"已结束",IF(NOT(ISNUMBER(K14)),"待填写胜负",IF(M14>J14,"敌幸存值超上限",IF(AND(I14=0,K14=0),"空波不可判败","原始波6")))) -> 已结束
A15: 下一套配置 | B15: 下一套配置 | C15: 下一套配置 | D15: 下一套配置 | E15: 下一套配置 | F15: 下一套配置 | G15: 下一套配置 | H15: 下一套配置 | I15: 下一套配置 | J15: 下一套配置 | K15: 下一套配置 | L15: 下一套配置 | M15: 下一套配置 | N15: 下一套配置 | O15: 下一套配置 | P15: 下一套配置 | Q15: 下一套配置 | R15: 下一套配置 | S15: 下一套配置
A16: B | B16: 1 | C16: 2 | D16: 0 | E16: 0 | F16: 0 | G16: 0 | H16: =C16*敌兵与开局!$C$9+D16*敌兵与开局!$C$10+E16*敌兵与开局!$C$11+F16*敌兵与开局!$C$12+G16*敌兵与开局!$C$13 -> 140 | I16: =SUM(C16:G16) -> 2 | J16: =C16*敌兵与开局!$F$9+D16*敌兵与开局!$F$10+E16*敌兵与开局!$F$11+F16*敌兵与开局!$F$12+G16*敌兵与开局!$F$13 -> 2 | K16: 1 | L16: 3 | M16: 0 | N16: =IF(OR(关卡总览!$D$10<=0,NOT(ISNUMBER(K16))),0,IF(K16=1,B16+L16,0)) -> 4 | O16: =IF(OR(关卡总览!$D$10<=0,NOT(ISNUMBER(K16))),0,IF(K16=0,B16+M16,0)) -> 0 | P16: =MAX(0,关卡总览!$D$10-N16) -> 26 | Q16: =0+O16 -> 0 | R16: =MIN(关卡总览!$E$10+(B16-1)*关卡总览!$F$10,关卡总览!$G$10) -> 3 | S16: =IF(关卡总览!$D$10<=0,"已结束",IF(NOT(ISNUMBER(K16)),"待填写胜负",IF(M16>J16,"敌幸存值超上限",IF(AND(I16=0,K16=0),"空波不可判败","原始波1")))) -> 原始波1
A17: B | B17: 2 | C17: 1 | D17: 1 | E17: 0 | F17: 0 | G17: 0 | H17: =C17*敌兵与开局!$C$9+D17*敌兵与开局!$C$10+E17*敌兵与开局!$C$11+F17*敌兵与开局!$C$12+G17*敌兵与开局!$C$13 -> 125 | I17: =SUM(C17:G17) -> 2 | J17: =C17*敌兵与开局!$F$9+D17*敌兵与开局!$F$10+E17*敌兵与开局!$F$11+F17*敌兵与开局!$F$12+G17*敌兵与开局!$F$13 -> 3 | K17: 1 | L17: 3 | M17: 0 | N17: =IF(OR(P16<=0,NOT(ISNUMBER(K17))),0,IF(K17=1,B17+L17,0)) -> 5 | O17: =IF(OR(P16<=0,NOT(ISNUMBER(K17))),0,IF(K17=0,B17+M17,0)) -> 0 | P17: =MAX(0,P16-N17) -> 21 | Q17: =Q16+O17 -> 0 | R17: =MIN(关卡总览!$E$10+(B17-1)*关卡总览!$F$10,关卡总览!$G$10) -> 4 | S17: =IF(P16<=0,"已结束",IF(NOT(ISNUMBER(K17)),"待填写胜负",IF(M17>J17,"敌幸存值超上限",IF(AND(I17=0,K17=0),"空波不可判败","原始波2")))) -> 原始波2
A18: B | B18: 3 | C18: 2 | D18: 1 | E18: 0 | F18: 0 | G18: 0 | H18: =C18*敌兵与开局!$C$9+D18*敌兵与开局!$C$10+E18*敌兵与开局!$C$11+F18*敌兵与开局!$C$12+G18*敌兵与开局!$C$13 -> 195 | I18: =SUM(C18:G18) -> 3 | J18: =C18*敌兵与开局!$F$9+D18*敌兵与开局!$F$10+E18*敌兵与开局!$F$11+F18*敌兵与开局!$F$12+G18*敌兵与开局!$F$13 -> 4 | K18: 0 | L18: 0 | M18: 2 | N18: =IF(OR(P17<=0,NOT(ISNUMBER(K18))),0,IF(K18=1,B18+L18,0)) -> 0 | O18: =IF(OR(P17<=0,NOT(ISNUMBER(K18))),0,IF(K18=0,B18+M18,0)) -> 5 | P18: =MAX(0,P17-N18) -> 21 | Q18: =Q17+O18 -> 5 | R18: =MIN(关卡总览!$E$10+(B18-1)*关卡总览!$F$10,关卡总览!$G$10) -> 5 | S18: =IF(P17<=0,"已结束",IF(NOT(ISNUMBER(K18)),"待填写胜负",IF(M18>J18,"敌幸存值超上限",IF(AND(I18=0,K18=0),"空波不可判败","原始波3")))) -> 原始波3
A19: B | B19: 4 | C19: 0 | D19: 0 | E19: 0 | F19: 0 | G19: 0 | H19: =C19*敌兵与开局!$C$9+D19*敌兵与开局!$C$10+E19*敌兵与开局!$C$11+F19*敌兵与开局!$C$12+G19*敌兵与开局!$C$13 -> 0 | I19: =SUM(C19:G19) -> 0 | J19: =C19*敌兵与开局!$F$9+D19*敌兵与开局!$F$10+E19*敌兵与开局!$F$11+F19*敌兵与开局!$F$12+G19*敌兵与开局!$F$13 -> 0 | K19: 1 | L19: 3 | M19: 0 | N19: =IF(OR(P18<=0,NOT(ISNUMBER(K19))),0,IF(K19=1,B19+L19,0)) -> 7 | O19: =IF(OR(P18<=0,NOT(ISNUMBER(K19))),0,IF(K19=0,B19+M19,0)) -> 0 | P19: =MAX(0,P18-N19) -> 14 | Q19: =Q18+O19 -> 5 | R19: =MIN(关卡总览!$E$10+(B19-1)*关卡总览!$F$10,关卡总览!$G$10) -> 6 | S19: =IF(P18<=0,"已结束",IF(NOT(ISNUMBER(K19)),"待填写胜负",IF(M19>J19,"敌幸存值超上限",IF(AND(I19=0,K19=0),"空波不可判败","空波")))) -> 空波
A20: B | B20: 5 | C20: 1 | D20: 0 | E20: 1 | F20: 0 | G20: 0 | H20: =C20*敌兵与开局!$C$9+D20*敌兵与开局!$C$10+E20*敌兵与开局!$C$11+F20*敌兵与开局!$C$12+G20*敌兵与开局!$C$13 -> 170 | I20: =SUM(C20:G20) -> 2 | J20: =C20*敌兵与开局!$F$9+D20*敌兵与开局!$F$10+E20*敌兵与开局!$F$11+F20*敌兵与开局!$F$12+G20*敌兵与开局!$F$13 -> 2 | K20: 0 | L20: 0 | M20: 2 | N20: =IF(OR(P19<=0,NOT(ISNUMBER(K20))),0,IF(K20=1,B20+L20,0)) -> 0 | O20: =IF(OR(P19<=0,NOT(ISNUMBER(K20))),0,IF(K20=0,B20+M20,0)) -> 7 | P20: =MAX(0,P19-N20) -> 14 | Q20: =Q19+O20 -> 12 | R20: =MIN(关卡总览!$E$10+(B20-1)*关卡总览!$F$10,关卡总览!$G$10) -> 7 | S20: =IF(P19<=0,"已结束",IF(NOT(ISNUMBER(K20)),"待填写胜负",IF(M20>J20,"敌幸存值超上限",IF(AND(I20=0,K20=0),"空波不可判败","原始波5")))) -> 原始波5
A21: B | B21: 6 | C21: 1 | D21: 1 | E21: 0 | F21: 0 | G21: 0 | H21: =C21*敌兵与开局!$C$9+D21*敌兵与开局!$C$10+E21*敌兵与开局!$C$11+F21*敌兵与开局!$C$12+G21*敌兵与开局!$C$13 -> 125 | I21: =SUM(C21:G21) -> 2 | J21: =C21*敌兵与开局!$F$9+D21*敌兵与开局!$F$10+E21*敌兵与开局!$F$11+F21*敌兵与开局!$F$12+G21*敌兵与开局!$F$13 -> 3 | K21: 1 | L21: 3 | M21: 0 | N21: =IF(OR(P20<=0,NOT(ISNUMBER(K21))),0,IF(K21=1,B21+L21,0)) -> 9 | O21: =IF(OR(P20<=0,NOT(ISNUMBER(K21))),0,IF(K21=0,B21+M21,0)) -> 0 | P21: =MAX(0,P20-N21) -> 5 | Q21: =Q20+O21 -> 12 | R21: =MIN(关卡总览!$E$10+(B21-1)*关卡总览!$F$10,关卡总览!$G$10) -> 8 | S21: =IF(P20<=0,"已结束",IF(NOT(ISNUMBER(K21)),"待填写胜负",IF(M21>J21,"敌幸存值超上限",IF(AND(I21=0,K21=0),"空波不可判败","原始波6")))) -> 原始波6
A22: B | B22: 7 | C22: 1 | D22: 0 | E22: 0 | F22: 0 | G22: 0 | H22: =C22*敌兵与开局!$C$9+D22*敌兵与开局!$C$10+E22*敌兵与开局!$C$11+F22*敌兵与开局!$C$12+G22*敌兵与开局!$C$13 -> 70 | I22: =SUM(C22:G22) -> 1 | J22: =C22*敌兵与开局!$F$9+D22*敌兵与开局!$F$10+E22*敌兵与开局!$F$11+F22*敌兵与开局!$F$12+G22*敌兵与开局!$F$13 -> 1 | K22: 1 | L22: 2 | M22: 0 | N22: =IF(OR(P21<=0,NOT(ISNUMBER(K22))),0,IF(K22=1,B22+L22,0)) -> 9 | O22: =IF(OR(P21<=0,NOT(ISNUMBER(K22))),0,IF(K22=0,B22+M22,0)) -> 0 | P22: =MAX(0,P21-N22) -> 0 | Q22: =Q21+O22 -> 12 | R22: =MIN(关卡总览!$E$10+(B22-1)*关卡总览!$F$10,关卡总览!$G$10) -> 9 | S22: =IF(P21<=0,"已结束",IF(NOT(ISNUMBER(K22)),"待填写胜负",IF(M22>J22,"敌幸存值超上限",IF(AND(I22=0,K22=0),"空波不可判败","原始波7")))) -> 原始波7
A23: 下一套配置 | B23: 下一套配置 | C23: 下一套配置 | D23: 下一套配置 | E23: 下一套配置 | F23: 下一套配置 | G23: 下一套配置 | H23: 下一套配置 | I23: 下一套配置 | J23: 下一套配置 | K23: 下一套配置 | L23: 下一套配置 | M23: 下一套配置 | N23: 下一套配置 | O23: 下一套配置 | P23: 下一套配置 | Q23: 下一套配置 | R23: 下一套配置 | S23: 下一套配置
A24: C | B24: 1 | C24: 2 | D24: 0 | E24: 0 | F24: 0 | G24: 0 | H24: =C24*敌兵与开局!$C$9+D24*敌兵与开局!$C$10+E24*敌兵与开局!$C$11+F24*敌兵与开局!$C$12+G24*敌兵与开局!$C$13 -> 140 | I24: =SUM(C24:G24) -> 2 | J24: =C24*敌兵与开局!$F$9+D24*敌兵与开局!$F$10+E24*敌兵与开局!$F$11+F24*敌兵与开局!$F$12+G24*敌兵与开局!$F$13 -> 2 | K24: 1 | L24: 3 | M24: 0 | N24: =IF(OR(关卡总览!$D$11<=0,NOT(ISNUMBER(K24))),0,IF(K24=1,B24+L24,0)) -> 4 | O24: =IF(OR(关卡总览!$D$11<=0,NOT(ISNUMBER(K24))),0,IF(K24=0,B24+M24,0)) -> 0 | P24: =MAX(0,关卡总览!$D$11-N24) -> 30 | Q24: =0+O24 -> 0 | R24: =MIN(关卡总览!$E$11+(B24-1)*关卡总览!$F$11,关卡总览!$G$11) -> 3 | S24: =IF(关卡总览!$D$11<=0,"已结束",IF(NOT(ISNUMBER(K24)),"待填写胜负",IF(M24>J24,"敌幸存值超上限",IF(AND(I24=0,K24=0),"空波不可判败","原始波1")))) -> 原始波1
A25: C | B25: 2 | C25: 1 | D25: 0 | E25: 1 | F25: 0 | G25: 0 | H25: =C25*敌兵与开局!$C$9+D25*敌兵与开局!$C$10+E25*敌兵与开局!$C$11+F25*敌兵与开局!$C$12+G25*敌兵与开局!$C$13 -> 170 | I25: =SUM(C25:G25) -> 2 | J25: =C25*敌兵与开局!$F$9+D25*敌兵与开局!$F$10+E25*敌兵与开局!$F$11+F25*敌兵与开局!$F$12+G25*敌兵与开局!$F$13 -> 2 | K25: 1 | L25: 2 | M25: 0 | N25: =IF(OR(P24<=0,NOT(ISNUMBER(K25))),0,IF(K25=1,B25+L25,0)) -> 4 | O25: =IF(OR(P24<=0,NOT(ISNUMBER(K25))),0,IF(K25=0,B25+M25,0)) -> 0 | P25: =MAX(0,P24-N25) -> 26 | Q25: =Q24+O25 -> 0 | R25: =MIN(关卡总览!$E$11+(B25-1)*关卡总览!$F$11,关卡总览!$G$11) -> 4 | S25: =IF(P24<=0,"已结束",IF(NOT(ISNUMBER(K25)),"待填写胜负",IF(M25>J25,"敌幸存值超上限",IF(AND(I25=0,K25=0),"空波不可判败","原始波2")))) -> 原始波2
A26: C | B26: 3 | C26: 1 | D26: 2 | E26: 0 | F26: 0 | G26: 0 | H26: =C26*敌兵与开局!$C$9+D26*敌兵与开局!$C$10+E26*敌兵与开局!$C$11+F26*敌兵与开局!$C$12+G26*敌兵与开局!$C$13 -> 180 | I26: =SUM(C26:G26) -> 3 | J26: =C26*敌兵与开局!$F$9+D26*敌兵与开局!$F$10+E26*敌兵与开局!$F$11+F26*敌兵与开局!$F$12+G26*敌兵与开局!$F$13 -> 5 | K26: 0 | L26: 0 | M26: 2 | N26: =IF(OR(P25<=0,NOT(ISNUMBER(K26))),0,IF(K26=1,B26+L26,0)) -> 0 | O26: =IF(OR(P25<=0,NOT(ISNUMBER(K26))),0,IF(K26=0,B26+M26,0)) -> 5 | P26: =MAX(0,P25-N26) -> 26 | Q26: =Q25+O26 -> 5 | R26: =MIN(关卡总览!$E$11+(B26-1)*关卡总览!$F$11,关卡总览!$G$11) -> 5 | S26: =IF(P25<=0,"已结束",IF(NOT(ISNUMBER(K26)),"待填写胜负",IF(M26>J26,"敌幸存值超上限",IF(AND(I26=0,K26=0),"空波不可判败","原始波3")))) -> 原始波3
A27: C | B27: 4 | C27: 0 | D27: 0 | E27: 0 | F27: 0 | G27: 0 | H27: =C27*敌兵与开局!$C$9+D27*敌兵与开局!$C$10+E27*敌兵与开局!$C$11+F27*敌兵与开局!$C$12+G27*敌兵与开局!$C$13 -> 0 | I27: =SUM(C27:G27) -> 0 | J27: =C27*敌兵与开局!$F$9+D27*敌兵与开局!$F$10+E27*敌兵与开局!$F$11+F27*敌兵与开局!$F$12+G27*敌兵与开局!$F$13 -> 0 | K27: 1 | L27: 3 | M27: 0 | N27: =IF(OR(P26<=0,NOT(ISNUMBER(K27))),0,IF(K27=1,B27+L27,0)) -> 7 | O27: =IF(OR(P26<=0,NOT(ISNUMBER(K27))),0,IF(K27=0,B27+M27,0)) -> 0 | P27: =MAX(0,P26-N27) -> 19 | Q27: =Q26+O27 -> 5 | R27: =MIN(关卡总览!$E$11+(B27-1)*关卡总览!$F$11,关卡总览!$G$11) -> 6 | S27: =IF(P26<=0,"已结束",IF(NOT(ISNUMBER(K27)),"待填写胜负",IF(M27>J27,"敌幸存值超上限",IF(AND(I27=0,K27=0),"空波不可判败","空波")))) -> 空波
